Workbook

Sheet SCHEDULE OF VALUE WORKSHEET
A1: GENESIS CAPITAL
A3: CLIENT: | B3: Angeleno Investments
A4: DATE: | B4: 11.12.2025
A5: PROJECT: | B5: 10910 Huston Street
B6: DESCRIPTION OF WORK | C6: REHAB BUDGET | D6: PRE-FUNDING COSTS | E6: SCHEDULED VALUES | G6: Full Budget | J6: Spent To Date
A7: 1 | B7: SOFT COSTS | G7: OLD | H7: Delta | J7: OLD | K7: Delta
A8: 2 | B8: Site Security | C8: 20000 | D8: 9419.37 | E8: =SUM(C8-D8) -> 10580.63 | G8: 20000 | H8: =C8-G8 -> 0 | J8: 8669.37 | K8: =D8-J8 -> 750
A9: 3 | B9: Soils Inspection | C9: 4800 | D9: 4800 | E9: =SUM(C9-D9) -> 0 | G9: 4800 | H9: =C9-G9 -> 0 | J9: 4800 | K9: =D9-J9 -> 0
A10: =A9+1 -> 4 | B10: Offsites (Transformer) | C10: 20000 | D10: 0 | E10: =SUM(C10-D10) -> 20000 | G10: 20000 | H10: =C10-G10 -> 0 | J10: 0 | K10: =D10-J10 -> 0
A11: =A10+1 -> 5 | B11: Plan Check Fees | C11: 15000 | D11: 15000 | E11: =SUM(C11-D11) -> 0 | G11: 15000 | H11: =C11-G11 -> 0 | J11: 12665.22 | K11: =D11-J11 -> 2334.78
A12: =A11+1 -> 6 | B12: Permits | C12: =121785.82+61767.91 -> 183553.73 | D12: 183553.73 | E12: =SUM(C12-D12) -> 0 | G12: 121785.82 | H12: =C12-G12 -> 61767.91 | J12: 73183.5 | K12: =D12-J12 -> 110370.23
A13: =A12+1 -> 7 | B13: Survey | C13: 3805.23 | D13: 3805.23 | E13: =SUM(C13-D13) -> 0 | G13: 3805.23 | H13: =C13-G13 -> 0 | J13: 0 | K13: =D13-J13 -> 3805.23
A14: =A13+1 -> 8 | B14: Soils Engineer | C14: 6800 | D14: 6800 | E14: =SUM(C14-D14) -> 0 | G14: 6800 | H14: =C14-G14 -> 0 | J14: 3400 | K14: =D14-J14 -> 3400
A15: =A14+1 -> 9 | B15: Soils Permit + T24 | C15: 2500 | D15: 0 | E15: =SUM(C15-D15) -> 2500 | G15: 2500 | H15: =C15-G15 -> 0 | J15: 0 | K15: =D15-J15 -> 0
A16: =A15+1 -> 10 | B16: Special Inspections - Deputy | C16: 15000 | D16: 0 | E16: =SUM(C16-D16) -> 15000 | G16: 15000 | H16: =C16-G16 -> 0 | J16: 0 | K16: =D16-J16 -> 0
A17: =A16+1 -> 11 | B17: Architect | C17: 122917 | D17: 122917 | E17: =SUM(C17-D17) -> 0 | G17: 113100 | H17: =C17-G17 -> 9817 | J17: 109989.75 | K17: =D17-J17 -> 12927.25
A18: =A17+1 -> 12 | B18: Structural Engineer | C18: 36600 | D18: 36600 | E18: =SUM(C18-D18) -> 0 | G18: 31600 | H18: =C18-G18 -> 5000 | J18: 31600 | K18: =D18-J18 -> 5000
A19: =A18+1 -> 13 | B19: Structural Observation | C19: 8000 | D19: 0 | E19: =SUM(C19-D19) -> 8000 | G19: 8000 | H19: =C19-G19 -> 0 | J19: 0 | K19: =D19-J19 -> 0
A20: =A19+1 -> 14 | B20: Civil Engineering | C20: 20000 | D20: 20000 | E20: =SUM(C20-D20) -> 0 | G20: 20000 | H20: =C20-G20 -> 0 | J20: 18000 | K20: =D20-J20 -> 2000
A21: =A20+1 -> 15 | B21: Grading Permit | C21: 2313.4 | D21: 2313.4 | E21: =SUM(C21-D21) -> 0 | G21: 2313.4 | H21: =C21-G21 -> 0 | J21: 2313.4 | K21: =D21-J21 -> 0
A22: =A21+1 -> 16 | B22: Landscape Architect/Designer | C22: 4200 | D22: 4200 | E22: =SUM(C22-D22) -> 0 | G22: 4200 | H22: =C22-G22 -> 0 | J22: 2700 | K22: =D22-J22 -> 1500
A23: =A22+1 -> 17 | B23: Driveway Apron Permit | C23: 2500 | D23: 0 | E23: =SUM(C23-D23) -> 2500 | G23: 2500 | H23: =C23-G23 -> 0 | J23: 0 | K23: =D23-J23 -> 0
A24: =A23+1 -> 18 | B24: Punch List - Misc. | C24: 21962.77 | D24: 0 | E24: =SUM(C24-D24) -> 21962.77 | G24: 21983 | H24: =C24-G24 -> -20.23 | J24: 0 | K24: =D24-J24 -> 0
... A42: =A41+1 -> 36 | B42: Construction Management / Observation (OO) | C42: 55000 | D42: 5572.1 | E42: =SUM(C42-D42) -> 49427.9 | G42: 55000 | H42: =C42-G42 -> 0 | J42: 0 | K42: =D42-J42 -> 5572.1
A43: 37 | B43: CMFA Startup Fee | C43: 22800 | D43: 0 | E43: =SUM(C43-D43) -> 22800 | G43: 22800 | H43: =C43-G43 -> 0 | J43: 0 | K43: =D43-J43 -> 0
A44: 38 | B44: Non-Profit Start Up Fee | C44: 25000 | D44: 0 | E44: =SUM(C44-D44) -> 25000 | G44: 25000 | H44: =C44-G44 -> 0 | J44: 0 | K44: =D44-J44 -> 0
A45: =A44+1 -> 39 | B45: CMFA Construction Fee | C45: 12000 | D45: 0 | E45: =SUM(C45-D45) -> 12000 | G45: 12000 | H45: =C45-G45 -> 0 | J45: 0 | K45: =D45-J45 -> 0
A46: =A45+1 -> 40 | B46: Non-Profit Construction Fee | C46: 10000 | D46: 0 | E46: =SUM(C46-D46) -> 10000 | G46: 10000 | H46: =C46-G46 -> 0 | J46: 0 | K46: =D46-J46 -> 0
A47: =A46+1 -> 41 | B47: WTE Legal Costs for CMFA & Non-Profit Partner | C47: 20000 | D47: 0 | E47: =SUM(C47-D47) -> 20000 | F47: =SUM(C8:C47) -> 857521.21 | G47: 20000 | H47: =C47-G47 -> 0 | J47: 0 | K47: =D47-J47 -> 0
A48: 42 | B48: HARD COSTS | E48: =SUM(C48-D48) -> 0
A49: 43 | B49: GENERAL CONDITIONS | C49: 565545 | D49: 203429.76 | E49: =SUM(C49-D49) -> 362115.24 | G49: 565545 | H49: =C49-G49 -> 0 | J49: 197892.71 | K49: =D49-J49 -> 5537.05
A50: =A49+1 -> 44 | B50: GENERAL REQUIREMENT | C50: 135922 | D50: 11264.12 | E50: =SUM(C50-D50) -> 124657.88 | G50: 135922 | H50: =C50-G50 -> 0 | J50: 11264.12 | K50: =D50-J50 -> 0
A51: =A50+1 -> 45 | B51: SITE WORK | C51: 139049.51 | D51: 0 | E51: =SUM(C51-D51) -> 139049.51 | G51: 139049.51 | H51: =C51-G51 -> 0 | J51: 0 | K51: =D51-J51 -> 0
A52: =A51+1 -> 46 | B52: CONCRETE | C52: 253182 | D52: 0 | E52: =SUM(C52-D52) -> 253182 | G52: 253182 | H52: =C52-G52 -> 0 | J52: 0 | K52: =D52-J52 -> 0
A53: =A52+1 -> 47 | B53: MASONRY | C53: 3562.64 | D53: 0 | E53: =SUM(C53-D53) -> 3562.64 | G53: 3562.64 | H53: =C53-G53 -> 0 | J53: 0 | K53: =D53-J53 -> 0
A54: =A53+1 -> 48 | B54: METALS | C54: 324100 | D54: 0 | E54: =SUM(C54-D54) -> 324100 | G54: 324100 | H54: =C54-G54 -> 0 | J54: 0 | K54: =D54-J54 -> 0
A55: =A54+1 -> 49 | B55: FRAMING | C55: 818554 | D55: 0 | E55: =SUM(C55-D55) -> 818554 | G55: 818554 | H55: =C55-G55 -> 0 | J55: 0 | K55: =D55-J55 -> 0
A56: =A55+1 -> 50 | B56: COUNTERTOPS | C56: 56930 | D56: 0 | E56: =SUM(C56-D56) -> 56930 | G56: 56930 | H56: =C56-G56 -> 0 | J56: 0 | K56: =D56-J56 -> 0
A57: =A56+1 -> 51 | B57: CABINETS | C57: 56930 | D57: 0 | E57: =SUM(C57-D57) -> 56930 | G57: 56930 | H57: =C57-G57 -> 0 | J57: 0 | K57: =D57-J57 -> 0
A58: =A57+1 -> 52 | B58: THERMAL MOISTURE PROTECTION | C58: 173148 | D58: 0 | E58: =SUM(C58-D58) -> 173148 | G58: 173148 | H58: =C58-G58 -> 0 | J58: 0 | K58: =D58-J58 -> 0
...

Sheet Draw #1
A1: GENESIS CAPITAL DRAW REQUEST FORM
B3: CLIENT: | C3: ='SCHEDULE OF VALUE WORKSHEET'!$B$3 -> Angeleno Investments | H3: TOTAL COMPLETED TO DATE: | I3: =SUM(I137) -> 0 | J3: =IF(I3=0,"",I3/I7)
B4: PROJECT: | C4: ='SCHEDULE OF VALUE WORKSHEET'!B5 -> 10910 Huston Street | H4: REMAINING $ IN BUDGET: | I4: =SUM(G137) -> #REF!
B5: DATE: | C5: =TODAY() -> 45978 | H5: ORIGINAL SCHEDULE OF VALUES: | I5: =SUM(D137) -> #REF!
B6: DRAW REQUEST: | C6: =SUM(H137) -> 0 | H6: CHANGE ORDERS: | I6: =SUM(E137) -> 0
H7: REVISED SCHEDULE OF VALUES: | I7: =SUM(F137) -> #REF!
B9: DESCRIPTION OF WORK | D9: SCHEDULED VALUES | E9: + / - CHANGES | F9: REVISED VALUES | G9: REMAINING | H9: DRAW | I9: COMPLETED AND
G10: $ PER BUDGET | H10: 1 | I10: STORED TO DATE
A11: ='SCHEDULE OF VALUE WORKSHEET'!A7 -> 1 | B11: ='SCHEDULE OF VALUE WORKSHEET'!B7 -> SOFT COSTS | D11: =SUM('SCHEDULE OF VALUE WORKSHEET'!E7) -> 0 | E11: 0 | F11: =SUM(D11)+E11 -> 0 | G11: =SUM(F11-I11) -> 0 | H11: 0 | I11: =SUM(H11) -> 0 | J11: =IF(I11=0,"",I11/F11)
A12: ='SCHEDULE OF VALUE WORKSHEET'!A8 -> 2 | B12: ='SCHEDULE OF VALUE WORKSHEET'!B8 -> Site Security | D12: =SUM('SCHEDULE OF VALUE WORKSHEET'!E8) -> 10580.63 | E12: 0 | F12: =SUM(D12)+E12 -> 10580.63 | G12: =SUM(F12-I12) -> 10580.63 | H12: 0 | I12: =SUM(H12) -> 0 | J12: =IF(I12=0,"",I12/F12)
A13: ='SCHEDULE OF VALUE WORKSHEET'!A9 -> 3 | B13: ='SCHEDULE OF VALUE WORKSHEET'!B9 -> Soils Inspection | D13: =SUM('SCHEDULE OF VALUE WORKSHEET'!E9) -> 0 | E13: 0 | F13: =SUM(D13)+E13 -> 0 | G13: =SUM(F13-I13) -> 0 | H13: 0 | I13: =SUM(H13) -> 0 | J13: =IF(I13=0,"",I13/F13)
A14: ='SCHEDULE OF VALUE WORKSHEET'!A10 -> 4 | B14: ='SCHEDULE OF VALUE WORKSHEET'!B10 -> Offsites (Transformer) | D14: =SUM('SCHEDULE OF VALUE WORKSHEET'!E10) -> 20000 | E14: 0 | F14: =SUM(D14)+E14 -> 20000 | G14: =SUM(F14-I14) -> 20000 | H14: 0 | I14: =SUM(H14) -> 0 | J14: =IF(I14=0,"",I14/F14)
A15: ='SCHEDULE OF VALUE WORKSHEET'!A11 -> 5 | B15: ='SCHEDULE OF VALUE WORKSHEET'!B11 -> Plan Check Fees | D15: =SUM('SCHEDULE OF VALUE WORKSHEET'!E11) -> 0 | E15: 0 | F15: =SUM(D15)+E15 -> 0 | G15: =SUM(F15-I15) -> 0 | H15: 0 | I15: =SUM(H15) -> 0 | J15: =IF(I15=0,"",I15/F15)
A16: ='SCHEDULE OF VALUE WORKSHEET'!A12 -> 6 | B16: ='SCHEDULE OF VALUE WORKSHEET'!B12 -> Permits | D16: =SUM('SCHEDULE OF VALUE WORKSHEET'!E12) -> 0 | E16: 0 | F16: =SUM(D16)+E16 -> 0 | G16: =SUM(F16-I16) -> 0 | H16: 0 | I16: =SUM(H16) -> 0 | J16: =IF(I16=0,"",I16/F16)
A17: ='SCHEDULE OF VALUE WORKSHEET'!A13 -> 7 | B17: ='SCHEDULE OF VALUE WORKSHEET'!B13 -> Survey | D17: =SUM('SCHEDULE OF VALUE WORKSHEET'!E13) -> 0 | E17: 0 | F17: =SUM(D17)+E17 -> 0 | G17: =SUM(F17-I17) -> 0 | H17: 0 | I17: =SUM(H17) -> 0 | J17: =IF(I17=0,"",I17/F17)
A18: ='SCHEDULE OF VALUE WORKSHEET'!A14 -> 8 | B18: ='SCHEDULE OF VALUE WORKSHEET'!B14 -> Soils Engineer | D18: =SUM('SCHEDULE OF VALUE WORKSHEET'!E14) -> 0 | E18: 0 | F18: =SUM(D18)+E18 -> 0 | G18: =SUM(F18-I18) -> 0 | H18: 0 | I18: =SUM(H18) -> 0 | J18: =IF(I18=0,"",I18/F18)
A19: ='SCHEDULE OF VALUE WORKSHEET'!A15 -> 9 | B19: ='SCHEDULE OF VALUE WORKSHEET'!B15 -> Soils Permit + T24 | D19: =SUM('SCHEDULE OF VALUE WORKSHEET'!E15) -> 2500 | E19: 0 | F19: =SUM(D19)+E19 -> 2500 | G19: =SUM(F19-I19) -> 2500 | H19: 0 | I19: =SUM(H19) -> 0 | J19: =IF(I19=0,"",I19/F19)
A20: ='SCHEDULE OF VALUE WORKSHEET'!A16 -> 10 | B20: ='SCHEDULE OF VALUE WORKSHEET'!B16 -> Special Inspections - Deputy | D20: =SUM('SCHEDULE OF VALUE WORKSHEET'!E16) -> 15000 | E20: 0 | F20: =SUM(D20)+E20 -> 15000 | G20: =SUM(F20-I20) -> 15000 | H20: 0 | I20: =SUM(H20) -> 0 | J20: =IF(I20=0,"",I20/F20)
A21: ='SCHEDULE OF VALUE WORKSHEET'!A17 -> 11 | B21: ='SCHEDULE OF VALUE WORKSHEET'!B17 -> Architect | D21: =SUM('SCHEDULE OF VALUE WORKSHEET'!E17) -> 0 | E21: 0 | F21: =SUM(D21)+E21 -> 0 | G21: =SUM(F21-I21) -> 0 | H21: 0 | I21: =SUM(H21) -> 0 | J21: =IF(I21=0,"",I21/F21)
A22: ='SCHEDULE OF VALUE WORKSHEET'!A18 -> 12 | B22: ='SCHEDULE OF VALUE WORKSHEET'!B18 -> Structural Engineer | D22: =SUM('SCHEDULE OF VALUE WORKSHEET'!E18) -> 0 | E22: 0 | F22: =SUM(D22)+E22 -> 0 | G22: =SUM(F22-I22) -> 0 | H22: 0 | I22: =SUM(H22) -> 0 | J22: =IF(I22=0,"",I22/F22)
... A46: ='SCHEDULE OF VALUE WORKSHEET'!A42 -> 36 | B46: ='SCHEDULE OF VALUE WORKSHEET'!B42 -> Construction Management / Observation (OO) | D46: =SUM('SCHEDULE OF VALUE WORKSHEET'!E42) -> 49427.9 | E46: 0 | F46: =SUM(D46)+E46 -> 49427.9 | G46: =SUM(F46-I46) -> 49427.9 | H46: 0 | I46: =SUM(H46) -> 0 | J46: =IF(I46=0,"",I46/F46)
A47: ='SCHEDULE OF VALUE WORKSHEET'!#REF! -> #REF! | B47: ='SCHEDULE OF VALUE WORKSHEET'!#REF! -> #REF! | D47: =SUM('SCHEDULE OF VALUE WORKSHEET'!#REF!) -> #REF! | E47: 0 | F47: =SUM(D47)+E47 -> #REF! | G47: =SUM(F47-I47) -> #REF! | H47: 0 | I47: =SUM(H47) -> 0 | J47: =IF(I47=0,"",I47/F47)
A48: ='SCHEDULE OF VALUE WORKSHEET'!A43 -> 37 | B48: ='SCHEDULE OF VALUE WORKSHEET'!B43 -> CMFA Startup Fee | D48: =SUM('SCHEDULE OF VALUE WORKSHEET'!E43) -> 22800 | E48: 0 | F48: =SUM(D48)+E48 -> 22800 | G48: =SUM(F48-I48) -> 22800 | H48: 0 | I48: =SUM(H48) -> 0 | J48: =IF(I48=0,"",I48/F48)
A49: ='SCHEDULE OF VALUE WORKSHEET'!A44 -> 38 | B49: ='SCHEDULE OF VALUE WORKSHEET'!B44 -> Non-Profit Start Up Fee | D49: =SUM('SCHEDULE OF VALUE WORKSHEET'!E44) -> 25000 | E49: 0 | F49: =SUM(D49)+E49 -> 25000 | G49: =SUM(F49-I49) -> 25000 | H49: 0 | I49: =SUM(H49) -> 0 | J49: =IF(I49=0,"",I49/F49)
A50: ='SCHEDULE OF VALUE WORKSHEET'!A45 -> 39 | B50: ='SCHEDULE OF VALUE WORKSHEET'!B45 -> CMFA Construction Fee | D50: =SUM('SCHEDULE OF VALUE WORKSHEET'!E45) -> 12000 | E50: 0 | F50: =SUM(D50)+E50 -> 12000 | G50: =SUM(F50-I50) -> 12000 | H50: 0 | I50: =SUM(H50) -> 0 | J50: =IF(I50=0,"",I50/F50)
A51: ='SCHEDULE OF VALUE WORKSHEET'!A46 -> 40 | B51: ='SCHEDULE OF VALUE WORKSHEET'!B46 -> Non-Profit Construction Fee | D51: =SUM('SCHEDULE OF VALUE WORKSHEET'!E46) -> 10000 | E51: 0 | F51: =SUM(D51)+E51 -> 10000 | G51: =SUM(F51-I51) -> 10000 | H51: 0 | I51: =SUM(H51) -> 0 | J51: =IF(I51=0,"",I51/F51)
A52: ='SCHEDULE OF VALUE WORKSHEET'!A47 -> 41 | B52: ='SCHEDULE OF VALUE WORKSHEET'!B47 -> WTE Legal Costs for CMFA & Non-Profit Partner | D52: =SUM('SCHEDULE OF VALUE WORKSHEET'!E47) -> 20000 | E52: 0 | F52: =SUM(D52)+E52 -> 20000 | G52: =SUM(F52-I52) -> 20000 | H52: 0 | I52: =SUM(H52) -> 0 | J52: =IF(I52=0,"",I52/F52)
A53: ='SCHEDULE OF VALUE WORKSHEET'!#REF! -> #REF! | B53: ='SCHEDULE OF VALUE WORKSHEET'!#REF! -> #REF! | D53: =SUM('SCHEDULE OF VALUE WORKSHEET'!#REF!) -> #REF! | E53: 0 | F53: =SUM(D53)+E53 -> #REF! | G53: =SUM(F53-I53) -> #REF! | H53: 0 | I53: =SUM(H53) -> 0 | J53: =IF(I53=0,"",I53/F53)
A54: ='SCHEDULE OF VALUE WORKSHEET'!A49 -> 43 | B54: ='SCHEDULE OF VALUE WORKSHEET'!B49 -> GENERAL CONDITIONS | D54: =SUM('SCHEDULE OF VALUE WORKSHEET'!E49) -> 362115.24 | E54: 0 | F54: =SUM(D54)+E54 -> 362115.24 | G54: =SUM(F54-I54) -> 362115.24 | H54: 0 | I54: =SUM(H54) -> 0 | J54: =IF(I54=0,"",I54/F54)
A55: ='SCHEDULE OF VALUE WORKSHEET'!A50 -> 44 | B55: ='SCHEDULE OF VALUE WORKSHEET'!B50 -> GENERAL REQUIREMENT | D55: =SUM('SCHEDULE OF VALUE WORKSHEET'!E50) -> 124657.88 | E55: 0 | F55: =SUM(D55)+E55 -> 124657.88 | G55: =SUM(F55-I55) -> 124657.88 | H55: 0 | I55: =SUM(H55) -> 0 | J55: =IF(I55=0,"",I55/F55)
A56: ='SCHEDULE OF VALUE WORKSHEET'!A51 -> 45 | B56: ='SCHEDULE OF VALUE WORKSHEET'!B51 -> SITE WORK | D56: =SUM('SCHEDULE OF VALUE WORKSHEET'!E51) -> 139049.51 | E56: 0 | F56: =SUM(D56)+E56 -> 139049.51 | G56: =SUM(F56-I56) -> 139049.51 | H56: 0 | I56: =SUM(H56) -> 0 | J56: =IF(I56=0,"",I56/F56)
A57: ='SCHEDULE OF VALUE WORKSHEET'!A52 -> 46 | B57: ='SCHEDULE OF VALUE WORKSHEET'!B52 -> CONCRETE | D57: =SUM('SCHEDULE OF VALUE WORKSHEET'!E52) -> 253182 | E57: 0 | F57: =SUM(D57)+E57 -> 253182 | G57: =SUM(F57-I57) -> 253182 | H57: 0 | I57: =SUM(H57) -> 0 | J57: =IF(I57=0,"",I57/F57)
A58: ='SCHEDULE OF VALUE WORKSHEET'!A53 -> 47 | B58: ='SCHEDULE OF VALUE WORKSHEET'!B53 -> MASONRY | D58: =SUM('SCHEDULE OF VALUE WORKSHEET'!E53) -> 3562.64 | E58: 0 | F58: =SUM(D58)+E58 -> 3562.64 | G58: =SUM(F58-I58) -> 3562.64 | H58: 0 | I58: =SUM(H58) -> 0 | J58: =IF(I58=0,"",I58/F58)
A59: ='SCHEDULE OF VALUE WORKSHEET'!A54 -> 48 | B59: ='SCHEDULE OF VALUE WORKSHEET'!B54 -> METALS | D59: =SUM('SCHEDULE OF VALUE WORKSHEET'!E54) -> 324100 | E59: 0 | F59: =SUM(D59)+E59 -> 324100 | G59: =SUM(F59-I59) -> 324100 | H59: 0 | I59: =SUM(H59) -> 0 | J59: =IF(I59=0,"",I59/F59)
A60: ='SCHEDULE OF VALUE WORKSHEET'!A55 -> 49 | B60: ='SCHEDULE OF VALUE WORKSHEET'!B55 -> FRAMING | D60: =SUM('SCHEDULE OF VALUE WORKSHEET'!E55) -> 818554 | E60: 0 | F60: =SUM(D60)+E60 -> 818554 | G60: =SUM(F60-I60) -> 818554 | H60: 0 | I60: =SUM(H60) -> 0 | J60: =IF(I60=0,"",I60/F60)
A61: ='SCHEDULE OF VALUE WORKSHEET'!A56 -> 50 | B61: ='SCHEDULE OF VALUE WORKSHEET'!B56 -> COUNTERTOPS | D61: =SUM('SCHEDULE OF VALUE WORKSHEET'!E56) -> 56930 | E61: 0 | F61: =SUM(D61)+E61 -> 56930 | G61: =SUM(F61-I61) -> 56930 | H61: 0 | I61: =SUM(H61) -> 0 | J61: =IF(I61=0,"",I61/F61)
A62: ='SCHEDULE OF VALUE WORKSHEET'!A57 -> 51 | B62: ='SCHEDULE OF VALUE WORKSHEET'!B57 -> CABINETS | D62: =SUM('SCHEDULE OF VALUE WORKSHEET'!E57) -> 56930 | E62: 0 | F62: =SUM(D62)+E62 -> 56930 | G62: =SUM(F62-I62) -> 56930 | H62: 0 | I62: =SUM(H62) -> 0 | J62: =IF(I62=0,"",I62/F62)
A63: ='SCHEDULE OF VALUE WORKSHEET'!A58 -> 52 | B63: ='SCHEDULE OF VALUE WORKSHEET'!B58 -> THERMAL MOISTURE PROTECTION | D63: =SUM('SCHEDULE OF VALUE WORKSHEET'!E58) -> 173148 | E63: 0 | F63: =SUM(D63)+E63 -> 173148 | G63: =SUM(F63-I63) -> 173148 | H63: 0 | I63: =SUM(H63) -> 0 | J63: =IF(I63=0,"",I63/F63)
A64: ='SCHEDULE OF VALUE WORKSHEET'!A59 -> 53 | B64: ='SCHEDULE OF VALUE WORKSHEET'!B59 -> DOORS | D64: =SUM('SCHEDULE OF VALUE WORKSHEET'!E59) -> 204087.33 | E64: 0 | F64: =SUM(D64)+E64 -> 204087.33 | G64: =SUM(F64-I64) -> 204087.33 | H64: 0 | I64: =SUM(H64) -> 0 | J64: =IF(I64=0,"",I64/F64)
A65: ='SCHEDULE OF VALUE WORKSHEET'!A60 -> 54 | B65: ='SCHEDULE OF VALUE WORKSHEET'!B60 -> WINDOWS | D65: =SUM('SCHEDULE OF VALUE WORKSHEET'!E60) -> 106274.25 | E65: 0 | F65: =SUM(D65)+E65 -> 106274.25 | G65: =SUM(F65-I65) -> 106274.25 | H65: 0 | I65: =SUM(H65) -> 0 | J65: =IF(I65=0,"",I65/F65)
...

Sheet Draw #2
A1: GENESIS CAPITAL DRAW FORM
B3: CLIENT: | C3: ='SCHEDULE OF VALUE WORKSHEET'!$B$3 -> Angeleno Investments | I3: TOTAL COMPLETED TO DATE: | J3: =SUM(J137) -> 0 | K3: =SUM(J3)/J7 -> #REF!
B4: DATE: | C4: =TODAY() -> 45978 | I4: REMAINING $ IN BUDGET: | J4: =SUM(H137) -> #REF!
B5: PROJECT: | C5: ='SCHEDULE OF VALUE WORKSHEET'!B5 -> 10910 Huston Street | I5: ORIGINAL SCHEDULE OF VALUES: | J5: =SUM(D137) -> #REF!
B6: DRAW REQUEST: | C6: =SUM(I137) -> 0 | I6: CHANGE ORDERS: | J6: =SUM(F137) -> 0
I7: REVISED SCHEDULE OF VALUES: | J7: =SUM(G137) -> #REF!
B8: DESCRIPTION OF WORK | D8: SCHEDULED VALUES | E8: PREVIOUS | F8: + / - CHANGES | G8: REVISED VALUES | H8: REMAINING | I8: DRAW | J8: COMPLETED AND
E9: CHANGES | H9: BUDGET | I9: 2 | J9: STORED TO DATE
A10: ='SCHEDULE OF VALUE WORKSHEET'!A7 -> 1 | B10: ='SCHEDULE OF VALUE WORKSHEET'!B7 -> SOFT COSTS | D10: =SUM('SCHEDULE OF VALUE WORKSHEET'!E7) -> 0 | E10: =SUM('Draw #1'!E11) -> 0 | F10: 0 | G10: =SUM('Draw #1'!F11)+F10 -> 0 | H10: =SUM(G10-J10) -> 0 | I10: 0 | J10: =SUM(I10+'Draw #1'!I11) -> 0 | K10: =IF(J10=0,"",J10/G10)
A11: ='SCHEDULE OF VALUE WORKSHEET'!A8 -> 2 | B11: ='SCHEDULE OF VALUE WORKSHEET'!B8 -> Site Security | D11: =SUM('SCHEDULE OF VALUE WORKSHEET'!E8) -> 10580.63 | E11: =SUM('Draw #1'!E12) -> 0 | F11: 0 | G11: =SUM('Draw #1'!F12)+F11 -> 10580.63 | H11: =SUM(G11-J11) -> 10580.63 | I11: 0 | J11: =SUM(I11+'Draw #1'!I12) -> 0 | K11: =IF(J11=0,"",J11/G11)
A12: ='SCHEDULE OF VALUE WORKSHEET'!A9 -> 3 | B12: ='SCHEDULE OF VALUE WORKSHEET'!B9 -> Soils Inspection | D12: =SUM('SCHEDULE OF VALUE WORKSHEET'!E9) -> 0 | E12: =SUM('Draw #1'!E13) -> 0 | F12: 0 | G12: =SUM('Draw #1'!F13)+F12 -> 0 | H12: =SUM(G12-J12) -> 0 | I12: 0 | J12: =SUM(I12+'Draw #1'!I13) -> 0 | K12: =IF(J12=0,"",J12/G12)
A13: ='SCHEDULE OF VALUE WORKSHEET'!A10 -> 4 | B13: ='SCHEDULE OF VALUE WORKSHEET'!B10 -> Offsites (Transformer) | D13: =SUM('SCHEDULE OF VALUE WORKSHEET'!E10) -> 20000 | E13: =SUM('Draw #1'!E14) -> 0 | F13: 0 | G13: =SUM('Draw #1'!F14)+F13 -> 20000 | H13: =SUM(G13-J13) -> 20000 | I13: 0 | J13: =SUM(I13+'Draw #1'!I14) -> 0 | K13: =IF(J13=0,"",J13/G13)
A14: ='SCHEDULE OF VALUE WORKSHEET'!A11 -> 5 | B14: ='SCHEDULE OF VALUE WORKSHEET'!B11 -> Plan Check Fees | D14: =SUM('SCHEDULE OF VALUE WORKSHEET'!E11) -> 0 | E14: =SUM('Draw #1'!E15) -> 0 | F14: 0 | G14: =SUM('Draw #1'!F15)+F14 -> 0 | H14: =SUM(G14-J14) -> 0 | I14: 0 | J14: =SUM(I14+'Draw #1'!I15) -> 0 | K14: =IF(J14=0,"",J14/G14)
A15: ='SCHEDULE OF VALUE WORKSHEET'!A12 -> 6 | B15: ='SCHEDULE OF VALUE WORKSHEET'!B12 -> Permits | D15: =SUM('SCHEDULE OF VALUE WORKSHEET'!E12) -> 0 | E15: =SUM('Draw #1'!E16) -> 0 | F15: 0 | G15: =SUM('Draw #1'!F16)+F15 -> 0 | H15: =SUM(G15-J15) -> 0 | I15: 0 | J15: =SUM(I15+'Draw #1'!I16) -> 0 | K15: =IF(J15=0,"",J15/G15)
A16: ='SCHEDULE OF VALUE WORKSHEET'!A13 -> 7 | B16: ='SCHEDULE OF VALUE WORKSHEET'!B13 -> Survey | D16: =SUM('SCHEDULE OF VALUE WORKSHEET'!E13) -> 0 | E16: =SUM('Draw #1'!E17) -> 0 | F16: 0 | G16: =SUM('Draw #1'!F17)+F16 -> 0 | H16: =SUM(G16-J16) -> 0 | I16: 0 | J16: =SUM(I16+'Draw #1'!I17) -> 0 | K16: =IF(J16=0,"",J16/G16)
A17: ='SCHEDULE OF VALUE WORKSHEET'!A14 -> 8 | B17: ='SCHEDULE OF VALUE WORKSHEET'!B14 -> Soils Engineer | D17: =SUM('SCHEDULE OF VALUE WORKSHEET'!E14) -> 0 | E17: =SUM('Draw #1'!E18) -> 0 | F17: 0 | G17: =SUM('Draw #1'!F18)+F17 -> 0 | H17: =SUM(G17-J17) -> 0 | I17: 0 | J17: =SUM(I17+'Draw #1'!I18) -> 0 | K17: =IF(J17=0,"",J17/G17)
A18: ='SCHEDULE OF VALUE WORKSHEET'!A15 -> 9 | B18: ='SCHEDULE OF VALUE WORKSHEET'!B15 -> Soils Permit + T24 | D18: =SUM('SCHEDULE OF VALUE WORKSHEET'!E15) -> 2500 | E18: =SUM('Draw #1'!E19) -> 0 | F18: 0 | G18: =SUM('Draw #1'!F19)+F18 -> 2500 | H18: =SUM(G18-J18) -> 2500 | I18: 0 | J18: =SUM(I18+'Draw #1'!I19) -> 0 | K18: =IF(J18=0,"",J18/G18)
A19: ='SCHEDULE OF VALUE WORKSHEET'!A16 -> 10 | B19: ='SCHEDULE OF VALUE WORKSHEET'!B16 -> Special Inspections - Deputy | D19: =SUM('SCHEDULE OF VALUE WORKSHEET'!E16) -> 15000 | E19: =SUM('Draw #1'!E20) -> 0 | F19: 0 | G19: =SUM('Draw #1'!F20)+F19 -> 15000 | H19: =SUM(G19-J19) -> 15000 | I19: 0 | J19: =SUM(I19+'Draw #1'!I20) -> 0 | K19: =IF(J19=0,"",J19/G19)
A20: ='SCHEDULE OF VALUE WORKSHEET'!A17 -> 11 | B20: ='SCHEDULE OF VALUE WORKSHEET'!B17 -> Architect | D20: =SUM('SCHEDULE OF VALUE WORKSHEET'!E17) -> 0 | E20: =SUM('Draw #1'!E21) -> 0 | F20: 0 | G20: =SUM('Draw #1'!F21)+F20 -> 0 | H20: =SUM(G20-J20) -> 0 | I20: 0 | J20: =SUM(I20+'Draw #1'!I21) -> 0 | K20: =IF(J20=0,"",J20/G20)
A21: ='SCHEDULE OF VALUE WORKSHEET'!A18 -> 12 | B21: ='SCHEDULE OF VALUE WORKSHEET'!B18 -> Structural Engineer | D21: =SUM('SCHEDULE OF VALUE WORKSHEET'!E18) -> 0 | E21: =SUM('Draw #1'!E22) -> 0 | F21: 0 | G21: =SUM('Draw #1'!F22)+F21 -> 0 | H21: =SUM(G21-J21) -> 0 | I21: 0 | J21: =SUM(I21+'Draw #1'!I22) -> 0 | K21: =IF(J21=0,"",J21/G21)
... A45: ='SCHEDULE OF VALUE WORKSHEET'!A42 -> 36 | B45: ='SCHEDULE OF VALUE WORKSHEET'!B42 -> Construction Management / Observation (OO) | D45: =SUM('SCHEDULE OF VALUE WORKSHEET'!E42) -> 49427.9 | E45: =SUM('Draw #1'!E46) -> 0 | F45: 0 | G45: =SUM('Draw #1'!F46)+F45 -> 49427.9 | H45: =SUM(G45-J45) -> 49427.9 | I45: 0 | J45: =SUM(I45+'Draw #1'!I46) -> 0 | K45: =IF(J45=0,"",J45/G45)
A46: ='SCHEDULE OF VALUE WORKSHEET'!#REF! -> #REF! | B46: ='SCHEDULE OF VALUE WORKSHEET'!#REF! -> #REF! | D46: =SUM('SCHEDULE OF VALUE WORKSHEET'!#REF!) -> #REF! | E46: =SUM('Draw #1'!E47) -> 0 | F46: 0 | G46: =SUM('Draw #1'!F47)+F46 -> #REF! | H46: =SUM(G46-J46) -> #REF! | I46: 0 | J46: =SUM(I46+'Draw #1'!I47) -> 0 | K46: =IF(J46=0,"",J46/G46)
A47: ='SCHEDULE OF VALUE WORKSHEET'!A43 -> 37 | B47: ='SCHEDULE OF VALUE WORKSHEET'!B43 -> CMFA Startup Fee | D47: =SUM('SCHEDULE OF VALUE WORKSHEET'!E43) -> 22800 | E47: =SUM('Draw #1'!E48) -> 0 | F47: 0 | G47: =SUM('Draw #1'!F48)+F47 -> 22800 | H47: =SUM(G47-J47) -> 22800 | I47: 0 | J47: =SUM(I47+'Draw #1'!I48) -> 0 | K47: =IF(J47=0,"",J47/G47)
A48: ='SCHEDULE OF VALUE WORKSHEET'!A44 -> 38 | B48: ='SCHEDULE OF VALUE WORKSHEET'!B44 -> Non-Profit Start Up Fee | D48: =SUM('SCHEDULE OF VALUE WORKSHEET'!E44) -> 25000 | E48: =SUM('Draw #1'!E49) -> 0 | F48: 0 | G48: =SUM('Draw #1'!F49)+F48 -> 25000 | H48: =SUM(G48-J48) -> 25000 | I48: 0 | J48: =SUM(I48+'Draw #1'!I49) -> 0 | K48: =IF(J48=0,"",J48/G48)
A49: ='SCHEDULE OF VALUE WORKSHEET'!A45 -> 39 | B49: ='SCHEDULE OF VALUE WORKSHEET'!B45 -> CMFA Construction Fee | D49: =SUM('SCHEDULE OF VALUE WORKSHEET'!E45) -> 12000 | E49: =SUM('Draw #1'!E50) -> 0 | F49: 0 | G49: =SUM('Draw #1'!F50)+F49 -> 12000 | H49: =SUM(G49-J49) -> 12000 | I49: 0 | J49: =SUM(I49+'Draw #1'!I50) -> 0 | K49: =IF(J49=0,"",J49/G49)
A50: ='SCHEDULE OF VALUE WORKSHEET'!A46 -> 40 | B50: ='SCHEDULE OF VALUE WORKSHEET'!B46 -> Non-Profit Construction Fee | D50: =SUM('SCHEDULE OF VALUE WORKSHEET'!E46) -> 10000 | E50: =SUM('Draw #1'!E51) -> 0 | F50: 0 | G50: =SUM('Draw #1'!F51)+F50 -> 10000 | H50: =SUM(G50-J50) -> 10000 | I50: 0 | J50: =SUM(I50+'Draw #1'!I51) -> 0 | K50: =IF(J50=0,"",J50/G50)
A51: ='SCHEDULE OF VALUE WORKSHEET'!A47 -> 41 | B51: ='SCHEDULE OF VALUE WORKSHEET'!B47 -> WTE Legal Costs for CMFA & Non-Profit Partner | D51: =SUM('SCHEDULE OF VALUE WORKSHEET'!E47) -> 20000 | E51: =SUM('Draw #1'!E52) -> 0 | F51: 0 | G51: =SUM('Draw #1'!F52)+F51 -> 20000 | H51: =SUM(G51-J51) -> 20000 | I51: 0 | J51: =SUM(I51+'Draw #1'!I52) -> 0 | K51: =IF(J51=0,"",J51/G51)
A52: ='SCHEDULE OF VALUE WORKSHEET'!#REF! -> #REF! | B52: ='SCHEDULE OF VALUE WORKSHEET'!#REF! -> #REF! | D52: =SUM('SCHEDULE OF VALUE WORKSHEET'!#REF!) -> #REF! | E52: =SUM('Draw #1'!E53) -> 0 | F52: 0 | G52: =SUM('Draw #1'!F53)+F52 -> #REF! | H52: =SUM(G52-J52) -> #REF! | I52: 0 | J52: =SUM(I52+'Draw #1'!I53) -> 0 | K52: =IF(J52=0,"",J52/G52)
A53: ='SCHEDULE OF VALUE WORKSHEET'!A49 -> 43 | B53: ='SCHEDULE OF VALUE WORKSHEET'!B49 -> GENERAL CONDITIONS | D53: =SUM('SCHEDULE OF VALUE WORKSHEET'!E49) -> 362115.24 | E53: =SUM('Draw #1'!E54) -> 0 | F53: 0 | G53: =SUM('Draw #1'!F54)+F53 -> 362115.24 | H53: =SUM(G53-J53) -> 362115.24 | I53: 0 | J53: =SUM(I53+'Draw #1'!I54) -> 0 | K53: =IF(J53=0,"",J53/G53)
A54: ='SCHEDULE OF VALUE WORKSHEET'!A50 -> 44 | B54: ='SCHEDULE OF VALUE WORKSHEET'!B50 -> GENERAL REQUIREMENT | D54: =SUM('SCHEDULE OF VALUE WORKSHEET'!E50) -> 124657.88 | E54: =SUM('Draw #1'!E55) -> 0 | F54: 0 | G54: =SUM('Draw #1'!F55)+F54 -> 124657.88 | H54: =SUM(G54-J54) -> 124657.88 | I54: 0 | J54: =SUM(I54+'Draw #1'!I55) -> 0 | K54: =IF(J54=0,"",J54/G54)
A55: ='SCHEDULE OF VALUE WORKSHEET'!A51 -> 45 | B55: ='SCHEDULE OF VALUE WORKSHEET'!B51 -> SITE WORK | D55: =SUM('SCHEDULE OF VALUE WORKSHEET'!E51) -> 139049.51 | E55: =SUM('Draw #1'!E56) -> 0 | F55: 0 | G55: =SUM('Draw #1'!F56)+F55 -> 139049.51 | H55: =SUM(G55-J55) -> 139049.51 | I55: 0 | J55: =SUM(I55+'Draw #1'!I56) -> 0 | K55: =IF(J55=0,"",J55/G55)
A56: ='SCHEDULE OF VALUE WORKSHEET'!A52 -> 46 | B56: ='SCHEDULE OF VALUE WORKSHEET'!B52 -> CONCRETE | D56: =SUM('SCHEDULE OF VALUE WORKSHEET'!E52) -> 253182 | E56: =SUM('Draw #1'!E57) -> 0 | F56: 0 | G56: =SUM('Draw #1'!F57)+F56 -> 253182 | H56: =SUM(G56-J56) -> 253182 | I56: 0 | J56: =SUM(I56+'Draw #1'!I57) -> 0 | K56: =IF(J56=0,"",J56/G56)
A57: ='SCHEDULE OF VALUE WORKSHEET'!A53 -> 47 | B57: ='SCHEDULE OF VALUE WORKSHEET'!B53 -> MASONRY | D57: =SUM('SCHEDULE OF VALUE WORKSHEET'!E53) -> 3562.64 | E57: =SUM('Draw #1'!E58) -> 0 | F57: 0 | G57: =SUM('Draw #1'!F58)+F57 -> 3562.64 | H57: =SUM(G57-J57) -> 3562.64 | I57: 0 | J57: =SUM(I57+'Draw #1'!I58) -> 0 | K57: =IF(J57=0,"",J57/G57)
A58: ='SCHEDULE OF VALUE WORKSHEET'!A54 -> 48 | B58: ='SCHEDULE OF VALUE WORKSHEET'!B54 -> METALS | D58: =SUM('SCHEDULE OF VALUE WORKSHEET'!E54) -> 324100 | E58: =SUM('Draw #1'!E59) -> 0 | F58: 0 | G58: =SUM('Draw #1'!F59)+F58 -> 324100 | H58: =SUM(G58-J58) -> 324100 | I58: 0 | J58: =SUM(I58+'Draw #1'!I59) -> 0 | K58: =IF(J58=0,"",J58/G58)
A59: ='SCHEDULE OF VALUE WORKSHEET'!A55 -> 49 | B59: ='SCHEDULE OF VALUE WORKSHEET'!B55 -> FRAMING | D59: =SUM('SCHEDULE OF VALUE WORKSHEET'!E55) -> 818554 | E59: =SUM('Draw #1'!E60) -> 0 | F59: 0 | G59: =SUM('Draw #1'!F60)+F59 -> 818554 | H59: =SUM(G59-J59) -> 818554 | I59: 0 | J59: =SUM(I59+'Draw #1'!I60) -> 0 | K59: =IF(J59=0,"",J59/G59)
A60: ='SCHEDULE OF VALUE WORKSHEET'!A56 -> 50 | B60: ='SCHEDULE OF VALUE WORKSHEET'!B56 -> COUNTERTOPS | D60: =SUM('SCHEDULE OF VALUE WORKSHEET'!E56) -> 56930 | E60: =SUM('Draw #1'!E61) -> 0 | F60: 0 | G60: =SUM('Draw #1'!F61)+F60 -> 56930 | H60: =SUM(G60-J60) -> 56930 | I60: 0 | J60: =SUM(I60+'Draw #1'!I61) -> 0 | K60: =IF(J60=0,"",J60/G60)
A61: ='SCHEDULE OF VALUE WORKSHEET'!A57 -> 51 | B61: ='SCHEDULE OF VALUE WORKSHEET'!B57 -> CABINETS | D61: =SUM('SCHEDULE OF VALUE WORKSHEET'!E57) -> 56930 | E61: =SUM('Draw #1'!E62) -> 0 | F61: 0 | G61: =SUM('Draw #1'!F62)+F61 -> 56930 | H61: =SUM(G61-J61) -> 56930 | I61: 0 | J61: =SUM(I61+'Draw #1'!I62) -> 0 | K61: =IF(J61=0,"",J61/G61)
A62: ='SCHEDULE OF VALUE WORKSHEET'!A58 -> 52 | B62: ='SCHEDULE OF VALUE WORKSHEET'!B58 -> THERMAL MOISTURE PROTECTION | D62: =SUM('SCHEDULE OF VALUE WORKSHEET'!E58) -> 173148 | E62: =SUM('Draw #1'!E63) -> 0 | F62: 0 | G62: =SUM('Draw #1'!F63)+F62 -> 173148 | H62: =SUM(G62-J62) -> 173148 | I62: 0 | J62: =SUM(I62+'Draw #1'!I63) -> 0 | K62: =IF(J62=0,"",J62/G62)
A63: ='SCHEDULE OF VALUE WORKSHEET'!A59 -> 53 | B63: ='SCHEDULE OF VALUE WORKSHEET'!B59 -> DOORS | D63: =SUM('SCHEDULE OF VALUE WORKSHEET'!E59) -> 204087.33 | E63: =SUM('Draw #1'!E64) -> 0 | F63: 0 | G63: =SUM('Draw #1'!F64)+F63 -> 204087.33 | H63: =SUM(G63-J63) -> 204087.33 | I63: 0 | J63: =SUM(I63+'Draw #1'!I64) -> 0 | K63: =IF(J63=0,"",J63/G63)
A64: ='SCHEDULE OF VALUE WORKSHEET'!A60 -> 54 | B64: ='SCHEDULE OF VALUE WORKSHEET'!B60 -> WINDOWS | D64: =SUM('SCHEDULE OF VALUE WORKSHEET'!E60) -> 106274.25 | E64: =SUM('Draw #1'!E65) -> 0 | F64: 0 | G64: =SUM('Draw #1'!F65)+F64 -> 106274.25 | H64: =SUM(G64-J64) -> 106274.25 | I64: 0 | J64: =SUM(I64+'Draw #1'!I65) -> 0 | K64: =IF(J64=0,"",J64/G64)
...

Sheet Draw #3
A1: GENESIS CAPITAL DRAW FORM
B3: CLIENT: | C3: ='SCHEDULE OF VALUE WORKSHEET'!$B$3 -> Angeleno Investments | I3: TOTAL COMPLETED TO DATE: | J3: =SUM(J137) -> 0 | K3: =SUM(J3)/J7 -> #REF!
B4: DATE: | C4: =TODAY() -> 45978 | I4: REMAINING $ IN BUDGET: | J4: =SUM(H137) -> #REF!
B5: PROJECT: | C5: ='SCHEDULE OF VALUE WORKSHEET'!B5 -> 10910 Huston Street | I5: ORIGINAL SCHEDULE OF VALUES: | J5: =SUM(D137) -> #REF!
B6: DRAW REQUEST: | C6: =SUM(I137) -> 0 | I6: CHANGE ORDERS: | J6: =SUM(F137) -> 0
I7: REVISED SCHEDULE OF VALUES: | J7: =SUM(G137) -> #REF!
B8: DESCRIPTION OF WORK | D8: SCHEDULED VALUES | E8: PREVIOUS | F8: + / - CHANGES | G8: REVISED VALUES | H8: REMAINING | I8: DRAW | J8: COMPLETED AND
E9: CHANGES | H9: BUDGET | I9: 3 | J9: STORED TO DATE
A10: ='SCHEDULE OF VALUE WORKSHEET'!A7 -> 1 | B10: ='SCHEDULE OF VALUE WORKSHEET'!B7 -> SOFT COSTS | D10: =SUM('SCHEDULE OF VALUE WORKSHEET'!E7) -> 0 | E10: =SUM('Draw #2'!E10:F10) -> 0 | F10: 0 | G10: =SUM('Draw #2'!G10)+F10 -> 0 | H10: =SUM(G10-J10) -> 0 | I10: 0 | J10: =SUM(I10+'Draw #2'!J10) -> 0 | K10: =IF(J10=0,"",J10/G10)
A11: ='SCHEDULE OF VALUE WORKSHEET'!A8 -> 2 | B11: ='SCHEDULE OF VALUE WORKSHEET'!B8 -> Site Security | D11: =SUM('SCHEDULE OF VALUE WORKSHEET'!E8) -> 10580.63 | E11: =SUM('Draw #2'!E11:F11) -> 0 | F11: 0 | G11: =SUM('Draw #2'!G11)+F11 -> 10580.63 | H11: =SUM(G11-J11) -> 10580.63 | I11: 0 | J11: =SUM(I11+'Draw #2'!J11) -> 0 | K11: =IF(J11=0,"",J11/G11)
A12: ='SCHEDULE OF VALUE WORKSHEET'!A9 -> 3 | B12: ='SCHEDULE OF VALUE WORKSHEET'!B9 -> Soils Inspection | D12: =SUM('SCHEDULE OF VALUE WORKSHEET'!E9) -> 0 | E12: =SUM('Draw #2'!E12:F12) -> 0 | F12: 0 | G12: =SUM('Draw #2'!G12)+F12 -> 0 | H12: =SUM(G12-J12) -> 0 | I12: 0 | J12: =SUM(I12+'Draw #2'!J12) -> 0 | K12: =IF(J12=0,"",J12/G12)
A13: ='SCHEDULE OF VALUE WORKSHEET'!A10 -> 4 | B13: ='SCHEDULE OF VALUE WORKSHEET'!B10 -> Offsites (Transformer) | D13: =SUM('SCHEDULE OF VALUE WORKSHEET'!E10) -> 20000 | E13: =SUM('Draw #2'!E13:F13) -> 0 | F13: 0 | G13: =SUM('Draw #2'!G13)+F13 -> 20000 | H13: =SUM(G13-J13) -> 20000 | I13: 0 | J13: =SUM(I13+'Draw #2'!J13) -> 0 | K13: =IF(J13=0,"",J13/G13)
A14: ='SCHEDULE OF VALUE WORKSHEET'!A11 -> 5 | B14: ='SCHEDULE OF VALUE WORKSHEET'!B11 -> Plan Check Fees | D14: =SUM('SCHEDULE OF VALUE WORKSHEET'!E11) -> 0 | E14: =SUM('Draw #2'!E14:F14) -> 0 | F14: 0 | G14: =SUM('Draw #2'!G14)+F14 -> 0 | H14: =SUM(G14-J14) -> 0 | I14: 0 | J14: =SUM(I14+'Draw #2'!J14) -> 0 | K14: =IF(J14=0,"",J14/G14)
A15: ='SCHEDULE OF VALUE WORKSHEET'!A12 -> 6 | B15: ='SCHEDULE OF VALUE WORKSHEET'!B12 -> Permits | D15: =SUM('SCHEDULE OF VALUE WORKSHEET'!E12) -> 0 | E15: =SUM('Draw #2'!E15:F15) -> 0 | F15: 0 | G15: =SUM('Draw #2'!G15)+F15 -> 0 | H15: =SUM(G15-J15) -> 0 | I15: 0 | J15: =SUM(I15+'Draw #2'!J15) -> 0 | K15: =IF(J15=0,"",J15/G15)
A16: ='SCHEDULE OF VALUE WORKSHEET'!A13 -> 7 | B16: ='SCHEDULE OF VALUE WORKSHEET'!B13 -> Survey | D16: =SUM('SCHEDULE OF VALUE WORKSHEET'!E13) -> 0 | E16: =SUM('Draw #2'!E16:F16) -> 0 | F16: 0 | G16: =SUM('Draw #2'!G16)+F16 -> 0 | H16: =SUM(G16-J16) -> 0 | I16: 0 | J16: =SUM(I16+'Draw #2'!J16) -> 0 | K16: =IF(J16=0,"",J16/G16)
A17: ='SCHEDULE OF VALUE WORKSHEET'!A14 -> 8 | B17: ='SCHEDULE OF VALUE WORKSHEET'!B14 -> Soils Engineer | D17: =SUM('SCHEDULE OF VALUE WORKSHEET'!E14) -> 0 | E17: =SUM('Draw #2'!E17:F17) -> 0 | F17: 0 | G17: =SUM('Draw #2'!G17)+F17 -> 0 | H17: =SUM(G17-J17) -> 0 | I17: 0 | J17: =SUM(I17+'Draw #2'!J17) -> 0 | K17: =IF(J17=0,"",J17/G17)
A18: ='SCHEDULE OF VALUE WORKSHEET'!A15 -> 9 | B18: ='SCHEDULE OF VALUE WORKSHEET'!B15 -> Soils Permit + T24 | D18: =SUM('SCHEDULE OF VALUE WORKSHEET'!E15) -> 2500 | E18: =SUM('Draw #2'!E18:F18) -> 0 | F18: 0 | G18: =SUM('Draw #2'!G18)+F18 -> 2500 | H18: =SUM(G18-J18) -> 2500 | I18: 0 | J18: =SUM(I18+'Draw #2'!J18) -> 0 | K18: =IF(J18=0,"",J18/G18)
A19: ='SCHEDULE OF VALUE WORKSHEET'!A16 -> 10 | B19: ='SCHEDULE OF VALUE WORKSHEET'!B16 -> Special Inspections - Deputy | D19: =SUM('SCHEDULE OF VALUE WORKSHEET'!E16) -> 15000 | E19: =SUM('Draw #2'!E19:F19) -> 0 | F19: 0 | G19: =SUM('Draw #2'!G19)+F19 -> 15000 | H19: =SUM(G19-J19) -> 15000 | I19: 0 | J19: =SUM(I19+'Draw #2'!J19) -> 0 | K19: =IF(J19=0,"",J19/G19)
A20: ='SCHEDULE OF VALUE WORKSHEET'!A17 -> 11 | B20: ='SCHEDULE OF VALUE WORKSHEET'!B17 -> Architect | D20: =SUM('SCHEDULE OF VALUE WORKSHEET'!E17) -> 0 | E20: =SUM('Draw #2'!E20:F20) -> 0 | F20: 0 | G20: =SUM('Draw #2'!G20)+F20 -> 0 | H20: =SUM(G20-J20) -> 0 | I20: 0 | J20: =SUM(I20+'Draw #2'!J20) -> 0 | K20: =IF(J20=0,"",J20/G20)
A21: ='SCHEDULE OF VALUE WORKSHEET'!A18 -> 12 | B21: ='SCHEDULE OF VALUE WORKSHEET'!B18 -> Structural Engineer | D21: =SUM('SCHEDULE OF VALUE WORKSHEET'!E18) -> 0 | E21: =SUM('Draw #2'!E21:F21) -> 0 | F21: 0 | G21: =SUM('Draw #2'!G21)+F21 -> 0 | H21: =SUM(G21-J21) -> 0 | I21: 0 | J21: =SUM(I21+'Draw #2'!J21) -> 0 | K21: =IF(J21=0,"",J21/G21)
... A45: ='SCHEDULE OF VALUE WORKSHEET'!A42 -> 36 | B45: ='SCHEDULE OF VALUE WORKSHEET'!B42 -> Construction Management / Observation (OO) | D45: =SUM('SCHEDULE OF VALUE WORKSHEET'!E42) -> 49427.9 | E45: =SUM('Draw #2'!E45:F45) -> 0 | F45: 0 | G45: =SUM('Draw #2'!G45)+F45 -> 49427.9 | H45: =SUM(G45-J45) -> 49427.9 | I45: 0 | J45: =SUM(I45+'Draw #2'!J45) -> 0 | K45: =IF(J45=0,"",J45/G45)
A46: ='SCHEDULE OF VALUE WORKSHEET'!#REF! -> #REF! | B46: ='SCHEDULE OF VALUE WORKSHEET'!#REF! -> #REF! | D46: =SUM('SCHEDULE OF VALUE WORKSHEET'!#REF!) -> #REF! | E46: =SUM('Draw #2'!E46:F46) -> 0 | F46: 0 | G46: =SUM('Draw #2'!G46)+F46 -> #REF! | H46: =SUM(G46-J46) -> #REF! | I46: 0 | J46: =SUM(I46+'Draw #2'!J46) -> 0 | K46: =IF(J46=0,"",J46/G46)
A47: ='SCHEDULE OF VALUE WORKSHEET'!A43 -> 37 | B47: ='SCHEDULE OF VALUE WORKSHEET'!B43 -> CMFA Startup Fee | D47: =SUM('SCHEDULE OF VALUE WORKSHEET'!E43) -> 22800 | E47: =SUM('Draw #2'!E47:F47) -> 0 | F47: 0 | G47: =SUM('Draw #2'!G47)+F47 -> 22800 | H47: =SUM(G47-J47) -> 22800 | I47: 0 | J47: =SUM(I47+'Draw #2'!J47) -> 0 | K47: =IF(J47=0,"",J47/G47)
A48: ='SCHEDULE OF VALUE WORKSHEET'!A44 -> 38 | B48: ='SCHEDULE OF VALUE WORKSHEET'!B44 -> Non-Profit Start Up Fee | D48: =SUM('SCHEDULE OF VALUE WORKSHEET'!E44) -> 25000 | E48: =SUM('Draw #2'!E48:F48) -> 0 | F48: 0 | G48: =SUM('Draw #2'!G48)+F48 -> 25000 | H48: =SUM(G48-J48) -> 25000 | I48: 0 | J48: =SUM(I48+'Draw #2'!J48) -> 0 | K48: =IF(J48=0,"",J48/G48)
A49: ='SCHEDULE OF VALUE WORKSHEET'!A45 -> 39 | B49: ='SCHEDULE OF VALUE WORKSHEET'!B45 -> CMFA Construction Fee | D49: =SUM('SCHEDULE OF VALUE WORKSHEET'!E45) -> 12000 | E49: =SUM('Draw #2'!E49:F49) -> 0 | F49: 0 | G49: =SUM('Draw #2'!G49)+F49 -> 12000 | H49: =SUM(G49-J49) -> 12000 | I49: 0 | J49: =SUM(I49+'Draw #2'!J49) -> 0 | K49: =IF(J49=0,"",J49/G49)
A50: ='SCHEDULE OF VALUE WORKSHEET'!A46 -> 40 | B50: ='SCHEDULE OF VALUE WORKSHEET'!B46 -> Non-Profit Construction Fee | D50: =SUM('SCHEDULE OF VALUE WORKSHEET'!E46) -> 10000 | E50: =SUM('Draw #2'!E50:F50) -> 0 | F50: 0 | G50: =SUM('Draw #2'!G50)+F50 -> 10000 | H50: =SUM(G50-J50) -> 10000 | I50: 0 | J50: =SUM(I50+'Draw #2'!J50) -> 0 | K50: =IF(J50=0,"",J50/G50)
A51: ='SCHEDULE OF VALUE WORKSHEET'!A47 -> 41 | B51: ='SCHEDULE OF VALUE WORKSHEET'!B47 -> WTE Legal Costs for CMFA & Non-Profit Partner | D51: =SUM('SCHEDULE OF VALUE WORKSHEET'!E47) -> 20000 | E51: =SUM('Draw #2'!E51:F51) -> 0 | F51: 0 | G51: =SUM('Draw #2'!G51)+F51 -> 20000 | H51: =SUM(G51-J51) -> 20000 | I51: 0 | J51: =SUM(I51+'Draw #2'!J51) -> 0 | K51: =IF(J51=0,"",J51/G51)
A52: ='SCHEDULE OF VALUE WORKSHEET'!#REF! -> #REF! | B52: ='SCHEDULE OF VALUE WORKSHEET'!#REF! -> #REF! | D52: =SUM('SCHEDULE OF VALUE WORKSHEET'!#REF!) -> #REF! | E52: =SUM('Draw #2'!E52:F52) -> 0 | F52: 0 | G52: =SUM('Draw #2'!G52)+F52 -> #REF! | H52: =SUM(G52-J52) -> #REF! | I52: 0 | J52: =SUM(I52+'Draw #2'!J52) -> 0 | K52: =IF(J52=0,"",J52/G52)
A53: ='SCHEDULE OF VALUE WORKSHEET'!A49 -> 43 | B53: ='SCHEDULE OF VALUE WORKSHEET'!B49 -> GENERAL CONDITIONS | D53: =SUM('SCHEDULE OF VALUE WORKSHEET'!E49) -> 362115.24 | E53: =SUM('Draw #2'!E53:F53) -> 0 | F53: 0 | G53: =SUM('Draw #2'!G53)+F53 -> 362115.24 | H53: =SUM(G53-J53) -> 362115.24 | I53: 0 | J53: =SUM(I53+'Draw #2'!J53) -> 0 | K53: =IF(J53=0,"",J53/G53)
A54: ='SCHEDULE OF VALUE WORKSHEET'!A50 -> 44 | B54: ='SCHEDULE OF VALUE WORKSHEET'!B50 -> GENERAL REQUIREMENT | D54: =SUM('SCHEDULE OF VALUE WORKSHEET'!E50) -> 124657.88 | E54: =SUM('Draw #2'!E54:F54) -> 0 | F54: 0 | G54: =SUM('Draw #2'!G54)+F54 -> 124657.88 | H54: =SUM(G54-J54) -> 124657.88 | I54: 0 | J54: =SUM(I54+'Draw #2'!J54) -> 0 | K54: =IF(J54=0,"",J54/G54)
A55: ='SCHEDULE OF VALUE WORKSHEET'!A51 -> 45 | B55: ='SCHEDULE OF VALUE WORKSHEET'!B51 -> SITE WORK | D55: =SUM('SCHEDULE OF VALUE WORKSHEET'!E51) -> 139049.51 | E55: =SUM('Draw #2'!E55:F55) -> 0 | F55: 0 | G55: =SUM('Draw #2'!G55)+F55 -> 139049.51 | H55: =SUM(G55-J55) -> 139049.51 | I55: 0 | J55: =SUM(I55+'Draw #2'!J55) -> 0 | K55: =IF(J55=0,"",J55/G55)
A56: ='SCHEDULE OF VALUE WORKSHEET'!A52 -> 46 | B56: ='SCHEDULE OF VALUE WORKSHEET'!B52 -> CONCRETE | D56: =SUM('SCHEDULE OF VALUE WORKSHEET'!E52) -> 253182 | E56: =SUM('Draw #2'!E56:F56) -> 0 | F56: 0 | G56: =SUM('Draw #2'!G56)+F56 -> 253182 | H56: =SUM(G56-J56) -> 253182 | I56: 0 | J56: =SUM(I56+'Draw #2'!J56) -> 0 | K56: =IF(J56=0,"",J56/G56)
A57: ='SCHEDULE OF VALUE WORKSHEET'!A53 -> 47 | B57: ='SCHEDULE OF VALUE WORKSHEET'!B53 -> MASONRY | D57: =SUM('SCHEDULE OF VALUE WORKSHEET'!E53) -> 3562.64 | E57: =SUM('Draw #2'!E57:F57) -> 0 | F57: 0 | G57: =SUM('Draw #2'!G57)+F57 -> 3562.64 | H57: =SUM(G57-J57) -> 3562.64 | I57: 0 | J57: =SUM(I57+'Draw #2'!J57) -> 0 | K57: =IF(J57=0,"",J57/G57)
A58: ='SCHEDULE OF VALUE WORKSHEET'!A54 -> 48 | B58: ='SCHEDULE OF VALUE WORKSHEET'!B54 -> METALS | D58: =SUM('SCHEDULE OF VALUE WORKSHEET'!E54) -> 324100 | E58: =SUM('Draw #2'!E58:F58) -> 0 | F58: 0 | G58: =SUM('Draw #2'!G58)+F58 -> 324100 | H58: =SUM(G58-J58) -> 324100 | I58: 0 | J58: =SUM(I58+'Draw #2'!J58) -> 0 | K58: =IF(J58=0,"",J58/G58)
A59: ='SCHEDULE OF VALUE WORKSHEET'!A55 -> 49 | B59: ='SCHEDULE OF VALUE WORKSHEET'!B55 -> FRAMING | D59: =SUM('SCHEDULE OF VALUE WORKSHEET'!E55) -> 818554 | E59: =SUM('Draw #2'!E59:F59) -> 0 | F59: 0 | G59: =SUM('Draw #2'!G59)+F59 -> 818554 | H59: =SUM(G59-J59) -> 818554 | I59: 0 | J59: =SUM(I59+'Draw #2'!J59) -> 0 | K59: =IF(J59=0,"",J59/G59)
A60: ='SCHEDULE OF VALUE WORKSHEET'!A56 -> 50 | B60: ='SCHEDULE OF VALUE WORKSHEET'!B56 -> COUNTERTOPS | D60: =SUM('SCHEDULE OF VALUE WORKSHEET'!E56) -> 56930 | E60: =SUM('Draw #2'!E60:F60) -> 0 | F60: 0 | G60: =SUM('Draw #2'!G60)+F60 -> 56930 | H60: =SUM(G60-J60) -> 56930 | I60: 0 | J60: =SUM(I60+'Draw #2'!J60) -> 0 | K60: =IF(J60=0,"",J60/G60)
A61: ='SCHEDULE OF VALUE WORKSHEET'!A57 -> 51 | B61: ='SCHEDULE OF VALUE WORKSHEET'!B57 -> CABINETS | D61: =SUM('SCHEDULE OF VALUE WORKSHEET'!E57) -> 56930 | E61: =SUM('Draw #2'!E61:F61) -> 0 | F61: 0 | G61: =SUM('Draw #2'!G61)+F61 -> 56930 | H61: =SUM(G61-J61) -> 56930 | I61: 0 | J61: =SUM(I61+'Draw #2'!J61) -> 0 | K61: =IF(J61=0,"",J61/G61)
A62: ='SCHEDULE OF VALUE WORKSHEET'!A58 -> 52 | B62: ='SCHEDULE OF VALUE WORKSHEET'!B58 -> THERMAL MOISTURE PROTECTION | D62: =SUM('SCHEDULE OF VALUE WORKSHEET'!E58) -> 173148 | E62: =SUM('Draw #2'!E62:F62) -> 0 | F62: 0 | G62: =SUM('Draw #2'!G62)+F62 -> 173148 | H62: =SUM(G62-J62) -> 173148 | I62: 0 | J62: =SUM(I62+'Draw #2'!J62) -> 0 | K62: =IF(J62=0,"",J62/G62)
A63: ='SCHEDULE OF VALUE WORKSHEET'!A59 -> 53 | B63: ='SCHEDULE OF VALUE WORKSHEET'!B59 -> DOORS | D63: =SUM('SCHEDULE OF VALUE WORKSHEET'!E59) -> 204087.33 | E63: =SUM('Draw #2'!E63:F63) -> 0 | F63: 0 | G63: =SUM('Draw #2'!G63)+F63 -> 204087.33 | H63: =SUM(G63-J63) -> 204087.33 | I63: 0 | J63: =SUM(I63+'Draw #2'!J63) -> 0 | K63: =IF(J63=0,"",J63/G63)
A64: ='SCHEDULE OF VALUE WORKSHEET'!A60 -> 54 | B64: ='SCHEDULE OF VALUE WORKSHEET'!B60 -> WINDOWS | D64: =SUM('SCHEDULE OF VALUE WORKSHEET'!E60) -> 106274.25 | E64: =SUM('Draw #2'!E64:F64) -> 0 | F64: 0 | G64: =SUM('Draw #2'!G64)+F64 -> 106274.25 | H64: =SUM(G64-J64) -> 106274.25 | I64: 0 | J64: =SUM(I64+'Draw #2'!J64) -> 0 | K64: =IF(J64=0,"",J64/G64)
...

Sheet Draw #4
A1: GENESIS CAPITAL DRAW FORM
B3: CLIENT: | C3: ='SCHEDULE OF VALUE WORKSHEET'!$B$3 -> Angeleno Investments | I3: TOTAL COMPLETED TO DATE: | J3: =SUM(J137) -> 0 | K3: =SUM(J3)/J7 -> #REF!
B4: DATE: | C4: =TODAY() -> 45978 | I4: REMAINING $ IN BUDGET: | J4: =SUM(H137) -> #REF!
B5: PROJECT: | C5: ='SCHEDULE OF VALUE WORKSHEET'!B5 -> 10910 Huston Street | I5: ORIGINAL SCHEDULE OF VALUES: | J5: =SUM(D137) -> #REF!
B6: DRAW REQUEST: | C6: =SUM(I137) -> 0 | I6: CHANGE ORDERS: | J6: =SUM(F137) -> 0
I7: REVISED SCHEDULE OF VALUES: | J7: =SUM(G137) -> #REF!
B8: DESCRIPTION OF WORK | D8: SCHEDULED VALUES | E8: PREVIOUS | F8: + / - CHANGES | G8: REVISED VALUES | H8: REMAINING | I8: DRAW | J8: COMPLETED AND
E9: CHANGES | H9: BUDGET | I9: 4 | J9: STORED TO DATE
A10: ='SCHEDULE OF VALUE WORKSHEET'!A7 -> 1 | B10: ='SCHEDULE OF VALUE WORKSHEET'!B7 -> SOFT COSTS | D10: =SUM('SCHEDULE OF VALUE WORKSHEET'!E7) -> 0 | E10: =SUM('Draw #3'!E10:F10) -> 0 | F10: 0 | G10: =SUM('Draw #3'!G10)+'Draw #4'!F10 -> 0 | H10: =SUM(G10-J10) -> 0 | I10: 0 | J10: =SUM(I10+'Draw #3'!J10) -> 0 | K10: =IF(J10=0,"",J10/G10)
A11: ='SCHEDULE OF VALUE WORKSHEET'!A8 -> 2 | B11: ='SCHEDULE OF VALUE WORKSHEET'!B8 -> Site Security | D11: =SUM('SCHEDULE OF VALUE WORKSHEET'!E8) -> 10580.63 | E11: =SUM('Draw #3'!E11:F11) -> 0 | F11: 0 | G11: =SUM('Draw #3'!G11)+'Draw #4'!F11 -> 10580.63 | H11: =SUM(G11-J11) -> 10580.63 | I11: 0 | J11: =SUM(I11+'Draw #3'!J11) -> 0 | K11: =IF(J11=0,"",J11/G11)
A12: ='SCHEDULE OF VALUE WORKSHEET'!A9 -> 3 | B12: ='SCHEDULE OF VALUE WORKSHEET'!B9 -> Soils Inspection | D12: =SUM('SCHEDULE OF VALUE WORKSHEET'!E9) -> 0 | E12: =SUM('Draw #3'!E12:F12) -> 0 | F12: 0 | G12: =SUM('Draw #3'!G12)+'Draw #4'!F12 -> 0 | H12: =SUM(G12-J12) -> 0 | I12: 0 | J12: =SUM(I12+'Draw #3'!J12) -> 0 | K12: =IF(J12=0,"",J12/G12)
A13: ='SCHEDULE OF VALUE WORKSHEET'!A10 -> 4 | B13: ='SCHEDULE OF VALUE WORKSHEET'!B10 -> Offsites (Transformer) | D13: =SUM('SCHEDULE OF VALUE WORKSHEET'!E10) -> 20000 | E13: =SUM('Draw #3'!E13:F13) -> 0 | F13: 0 | G13: =SUM('Draw #3'!G13)+'Draw #4'!F13 -> 20000 | H13: =SUM(G13-J13) -> 20000 | I13: 0 | J13: =SUM(I13+'Draw #3'!J13) -> 0 | K13: =IF(J13=0,"",J13/G13)
A14: ='SCHEDULE OF VALUE WORKSHEET'!A11 -> 5 | B14: ='SCHEDULE OF VALUE WORKSHEET'!B11 -> Plan Check Fees | D14: =SUM('SCHEDULE OF VALUE WORKSHEET'!E11) -> 0 | E14: =SUM('Draw #3'!E14:F14) -> 0 | F14: 0 | G14: =SUM('Draw #3'!G14)+'Draw #4'!F14 -> 0 | H14: =SUM(G14-J14) -> 0 | I14: 0 | J14: =SUM(I14+'Draw #3'!J14) -> 0 | K14: =IF(J14=0,"",J14/G14)
A15: ='SCHEDULE OF VALUE WORKSHEET'!A12 -> 6 | B15: ='SCHEDULE OF VALUE WORKSHEET'!B12 -> Permits | D15: =SUM('SCHEDULE OF VALUE WORKSHEET'!E12) -> 0 | E15: =SUM('Draw #3'!E15:F15) -> 0 | F15: 0 | G15: =SUM('Draw #3'!G15)+'Draw #4'!F15 -> 0 | H15: =SUM(G15-J15) -> 0 | I15: 0 | J15: =SUM(I15+'Draw #3'!J15) -> 0 | K15: =IF(J15=0,"",J15/G15)
A16: ='SCHEDULE OF VALUE WORKSHEET'!A13 -> 7 | B16: ='SCHEDULE OF VALUE WORKSHEET'!B13 -> Survey | D16: =SUM('SCHEDULE OF VALUE WORKSHEET'!E13) -> 0 | E16: =SUM('Draw #3'!E16:F16) -> 0 | F16: 0 | G16: =SUM('Draw #3'!G16)+'Draw #4'!F16 -> 0 | H16: =SUM(G16-J16) -> 0 | I16: 0 | J16: =SUM(I16+'Draw #3'!J16) -> 0 | K16: =IF(J16=0,"",J16/G16)
A17: ='SCHEDULE OF VALUE WORKSHEET'!A14 -> 8 | B17: ='SCHEDULE OF VALUE WORKSHEET'!B14 -> Soils Engineer | D17: =SUM('SCHEDULE OF VALUE WORKSHEET'!E14) -> 0 | E17: =SUM('Draw #3'!E17:F17) -> 0 | F17: 0 | G17: =SUM('Draw #3'!G17)+'Draw #4'!F17 -> 0 | H17: =SUM(G17-J17) -> 0 | I17: 0 | J17: =SUM(I17+'Draw #3'!J17) -> 0 | K17: =IF(J17=0,"",J17/G17)
A18: ='SCHEDULE OF VALUE WORKSHEET'!A15 -> 9 | B18: ='SCHEDULE OF VALUE WORKSHEET'!B15 -> Soils Permit + T24 | D18: =SUM('SCHEDULE OF VALUE WORKSHEET'!E15) -> 2500 | E18: =SUM('Draw #3'!E18:F18) -> 0 | F18: 0 | G18: =SUM('Draw #3'!G18)+'Draw #4'!F18 -> 2500 | H18: =SUM(G18-J18) -> 2500 | I18: 0 | J18: =SUM(I18+'Draw #3'!J18) -> 0 | K18: =IF(J18=0,"",J18/G18)
A19: ='SCHEDULE OF VALUE WORKSHEET'!A16 -> 10 | B19: ='SCHEDULE OF VALUE WORKSHEET'!B16 -> Special Inspections - Deputy | D19: =SUM('SCHEDULE OF VALUE WORKSHEET'!E16) -> 15000 | E19: =SUM('Draw #3'!E19:F19) -> 0 | F19: 0 | G19: =SUM('Draw #3'!G19)+'Draw #4'!F19 -> 15000 | H19: =SUM(G19-J19) -> 15000 | I19: 0 | J19: =SUM(I19+'Draw #3'!J19) -> 0 | K19: =IF(J19=0,"",J19/G19)
A20: ='SCHEDULE OF VALUE WORKSHEET'!A17 -> 11 | B20: ='SCHEDULE OF VALUE WORKSHEET'!B17 -> Architect | D20: =SUM('SCHEDULE OF VALUE WORKSHEET'!E17) -> 0 | E20: =SUM('Draw #3'!E20:F20) -> 0 | F20: 0 | G20: =SUM('Draw #3'!G20)+'Draw #4'!F20 -> 0 | H20: =SUM(G20-J20) -> 0 | I20: 0 | J20: =SUM(I20+'Draw #3'!J20) -> 0 | K20: =IF(J20=0,"",J20/G20)
A21: ='SCHEDULE OF VALUE WORKSHEET'!A18 -> 12 | B21: ='SCHEDULE OF VALUE WORKSHEET'!B18 -> Structural Engineer | D21: =SUM('SCHEDULE OF VALUE WORKSHEET'!E18) -> 0 | E21: =SUM('Draw #3'!E21:F21) -> 0 | F21: 0 | G21: =SUM('Draw #3'!G21)+'Draw #4'!F21 -> 0 | H21: =SUM(G21-J21) -> 0 | I21: 0 | J21: =SUM(I21+'Draw #3'!J21) -> 0 | K21: =IF(J21=0,"",J21/G21)
... A45: ='SCHEDULE OF VALUE WORKSHEET'!A42 -> 36 | B45: ='SCHEDULE OF VALUE WORKSHEET'!B42 -> Construction Management / Observation (OO) | D45: =SUM('SCHEDULE OF VALUE WORKSHEET'!E42) -> 49427.9 | E45: =SUM('Draw #3'!E45:F45) -> 0 | F45: 0 | G45: =SUM('Draw #3'!G45)+'Draw #4'!F45 -> 49427.9 | H45: =SUM(G45-J45) -> 49427.9 | I45: 0 | J45: =SUM(I45+'Draw #3'!J45) -> 0 | K45: =IF(J45=0,"",J45/G45)
A46: ='SCHEDULE OF VALUE WORKSHEET'!#REF! -> #REF! | B46: ='SCHEDULE OF VALUE WORKSHEET'!#REF! -> #REF! | D46: =SUM('SCHEDULE OF VALUE WORKSHEET'!#REF!) -> #REF! | E46: =SUM('Draw #3'!E46:F46) -> 0 | F46: 0 | G46: =SUM('Draw #3'!G46)+'Draw #4'!F46 -> #REF! | H46: =SUM(G46-J46) -> #REF! | I46: 0 | J46: =SUM(I46+'Draw #3'!J46) -> 0 | K46: =IF(J46=0,"",J46/G46)
A47: ='SCHEDULE OF VALUE WORKSHEET'!A43 -> 37 | B47: ='SCHEDULE OF VALUE WORKSHEET'!B43 -> CMFA Startup Fee | D47: =SUM('SCHEDULE OF VALUE WORKSHEET'!E43) -> 22800 | E47: =SUM('Draw #3'!E47:F47) -> 0 | F47: 0 | G47: =SUM('Draw #3'!G47)+'Draw #4'!F47 -> 22800 | H47: =SUM(G47-J47) -> 22800 | I47: 0 | J47: =SUM(I47+'Draw #3'!J47) -> 0 | K47: =IF(J47=0,"",J47/G47)
A48: ='SCHEDULE OF VALUE WORKSHEET'!A44 -> 38 | B48: ='SCHEDULE OF VALUE WORKSHEET'!B44 -> Non-Profit Start Up Fee | D48: =SUM('SCHEDULE OF VALUE WORKSHEET'!E44) -> 25000 | E48: =SUM('Draw #3'!E48:F48) -> 0 | F48: 0 | G48: =SUM('Draw #3'!G48)+'Draw #4'!F48 -> 25000 | H48: =SUM(G48-J48) -> 25000 | I48: 0 | J48: =SUM(I48+'Draw #3'!J48) -> 0 | K48: =IF(J48=0,"",J48/G48)
A49: ='SCHEDULE OF VALUE WORKSHEET'!A45 -> 39 | B49: ='SCHEDULE OF VALUE WORKSHEET'!B45 -> CMFA Construction Fee | D49: =SUM('SCHEDULE OF VALUE WORKSHEET'!E45) -> 12000 | E49: =SUM('Draw #3'!E49:F49) -> 0 | F49: 0 | G49: =SUM('Draw #3'!G49)+'Draw #4'!F49 -> 12000 | H49: =SUM(G49-J49) -> 12000 | I49: 0 | J49: =SUM(I49+'Draw #3'!J49) -> 0 | K49: =IF(J49=0,"",J49/G49)
A50: ='SCHEDULE OF VALUE WORKSHEET'!A46 -> 40 | B50: ='SCHEDULE OF VALUE WORKSHEET'!B46 -> Non-Profit Construction Fee | D50: =SUM('SCHEDULE OF VALUE WORKSHEET'!E46) -> 10000 | E50: =SUM('Draw #3'!E50:F50) -> 0 | F50: 0 | G50: =SUM('Draw #3'!G50)+'Draw #4'!F50 -> 10000 | H50: =SUM(G50-J50) -> 10000 | I50: 0 | J50: =SUM(I50+'Draw #3'!J50) -> 0 | K50: =IF(J50=0,"",J50/G50)
A51: ='SCHEDULE OF VALUE WORKSHEET'!A47 -> 41 | B51: ='SCHEDULE OF VALUE WORKSHEET'!B47 -> WTE Legal Costs for CMFA & Non-Profit Partner | D51: =SUM('SCHEDULE OF VALUE WORKSHEET'!E47) -> 20000 | E51: =SUM('Draw #3'!E51:F51) -> 0 | F51: 0 | G51: =SUM('Draw #3'!G51)+'Draw #4'!F51 -> 20000 | H51: =SUM(G51-J51) -> 20000 | I51: 0 | J51: =SUM(I51+'Draw #3'!J51) -> 0 | K51: =IF(J51=0,"",J51/G51)
A52: ='SCHEDULE OF VALUE WORKSHEET'!#REF! -> #REF! | B52: ='SCHEDULE OF VALUE WORKSHEET'!#REF! -> #REF! | D52: =SUM('SCHEDULE OF VALUE WORKSHEET'!#REF!) -> #REF! | E52: =SUM('Draw #3'!E52:F52) -> 0 | F52: 0 | G52: =SUM('Draw #3'!G52)+'Draw #4'!F52 -> #REF! | H52: =SUM(G52-J52) -> #REF! | I52: 0 | J52: =SUM(I52+'Draw #3'!J52) -> 0 | K52: =IF(J52=0,"",J52/G52)
A53: ='SCHEDULE OF VALUE WORKSHEET'!A49 -> 43 | B53: ='SCHEDULE OF VALUE WORKSHEET'!B49 -> GENERAL CONDITIONS | D53: =SUM('SCHEDULE OF VALUE WORKSHEET'!E49) -> 362115.24 | E53: =SUM('Draw #3'!E53:F53) -> 0 | F53: 0 | G53: =SUM('Draw #3'!G53)+'Draw #4'!F53 -> 362115.24 | H53: =SUM(G53-J53) -> 362115.24 | I53: 0 | J53: =SUM(I53+'Draw #3'!J53) -> 0 | K53: =IF(J53=0,"",J53/G53)
A54: ='SCHEDULE OF VALUE WORKSHEET'!A50 -> 44 | B54: ='SCHEDULE OF VALUE WORKSHEET'!B50 -> GENERAL REQUIREMENT | D54: =SUM('SCHEDULE OF VALUE WORKSHEET'!E50) -> 124657.88 | E54: =SUM('Draw #3'!E54:F54) -> 0 | F54: 0 | G54: =SUM('Draw #3'!G54)+'Draw #4'!F54 -> 124657.88 | H54: =SUM(G54-J54) -> 124657.88 | I54: 0 | J54: =SUM(I54+'Draw #3'!J54) -> 0 | K54: =IF(J54=0,"",J54/G54)
A55: ='SCHEDULE OF VALUE WORKSHEET'!A51 -> 45 | B55: ='SCHEDULE OF VALUE WORKSHEET'!B51 -> SITE WORK | D55: =SUM('SCHEDULE OF VALUE WORKSHEET'!E51) -> 139049.51 | E55: =SUM('Draw #3'!E55:F55) -> 0 | F55: 0 | G55: =SUM('Draw #3'!G55)+'Draw #4'!F55 -> 139049.51 | H55: =SUM(G55-J55) -> 139049.51 | I55: 0 | J55: =SUM(I55+'Draw #3'!J55) -> 0 | K55: =IF(J55=0,"",J55/G55)
A56: ='SCHEDULE OF VALUE WORKSHEET'!A52 -> 46 | B56: ='SCHEDULE OF VALUE WORKSHEET'!B52 -> CONCRETE | D56: =SUM('SCHEDULE OF VALUE WORKSHEET'!E52) -> 253182 | E56: =SUM('Draw #3'!E56:F56) -> 0 | F56: 0 | G56: =SUM('Draw #3'!G56)+'Draw #4'!F56 -> 253182 | H56: =SUM(G56-J56) -> 253182 | I56: 0 | J56: =SUM(I56+'Draw #3'!J56) -> 0 | K56: =IF(J56=0,"",J56/G56)
A57: ='SCHEDULE OF VALUE WORKSHEET'!A53 -> 47 | B57: ='SCHEDULE OF VALUE WORKSHEET'!B53 -> MASONRY | D57: =SUM('SCHEDULE OF VALUE WORKSHEET'!E53) -> 3562.64 | E57: =SUM('Draw #3'!E57:F57) -> 0 | F57: 0 | G57: =SUM('Draw #3'!G57)+'Draw #4'!F57 -> 3562.64 | H57: =SUM(G57-J57) -> 3562.64 | I57: 0 | J57: =SUM(I57+'Draw #3'!J57) -> 0 | K57: =IF(J57=0,"",J57/G57)
A58: ='SCHEDULE OF VALUE WORKSHEET'!A54 -> 48 | B58: ='SCHEDULE OF VALUE WORKSHEET'!B54 -> METALS | D58: =SUM('SCHEDULE OF VALUE WORKSHEET'!E54) -> 324100 | E58: =SUM('Draw #3'!E58:F58) -> 0 | F58: 0 | G58: =SUM('Draw #3'!G58)+'Draw #4'!F58 -> 324100 | H58: =SUM(G58-J58) -> 324100 | I58: 0 | J58: =SUM(I58+'Draw #3'!J58) -> 0 | K58: =IF(J58=0,"",J58/G58)
A59: ='SCHEDULE OF VALUE WORKSHEET'!A55 -> 49 | B59: ='SCHEDULE OF VALUE WORKSHEET'!B55 -> FRAMING | D59: =SUM('SCHEDULE OF VALUE WORKSHEET'!E55) -> 818554 | E59: =SUM('Draw #3'!E59:F59) -> 0 | F59: 0 | G59: =SUM('Draw #3'!G59)+'Draw #4'!F59 -> 818554 | H59: =SUM(G59-J59) -> 818554 | I59: 0 | J59: =SUM(I59+'Draw #3'!J59) -> 0 | K59: =IF(J59=0,"",J59/G59)
A60: ='SCHEDULE OF VALUE WORKSHEET'!A56 -> 50 | B60: ='SCHEDULE OF VALUE WORKSHEET'!B56 -> COUNTERTOPS | D60: =SUM('SCHEDULE OF VALUE WORKSHEET'!E56) -> 56930 | E60: =SUM('Draw #3'!E60:F60) -> 0 | F60: 0 | G60: =SUM('Draw #3'!G60)+'Draw #4'!F60 -> 56930 | H60: =SUM(G60-J60) -> 56930 | I60: 0 | J60: =SUM(I60+'Draw #3'!J60) -> 0 | K60: =IF(J60=0,"",J60/G60)
A61: ='SCHEDULE OF VALUE WORKSHEET'!A57 -> 51 | B61: ='SCHEDULE OF VALUE WORKSHEET'!B57 -> CABINETS | D61: =SUM('SCHEDULE OF VALUE WORKSHEET'!E57) -> 56930 | E61: =SUM('Draw #3'!E61:F61) -> 0 | F61: 0 | G61: =SUM('Draw #3'!G61)+'Draw #4'!F61 -> 56930 | H61: =SUM(G61-J61) -> 56930 | I61: 0 | J61: =SUM(I61+'Draw #3'!J61) -> 0 | K61: =IF(J61=0,"",J61/G61)
A62: ='SCHEDULE OF VALUE WORKSHEET'!A58 -> 52 | B62: ='SCHEDULE OF VALUE WORKSHEET'!B58 -> THERMAL MOISTURE PROTECTION | D62: =SUM('SCHEDULE OF VALUE WORKSHEET'!E58) -> 173148 | E62: =SUM('Draw #3'!E62:F62) -> 0 | F62: 0 | G62: =SUM('Draw #3'!G62)+'Draw #4'!F62 -> 173148 | H62: =SUM(G62-J62) -> 173148 | I62: 0 | J62: =SUM(I62+'Draw #3'!J62) -> 0 | K62: =IF(J62=0,"",J62/G62)
A63: ='SCHEDULE OF VALUE WORKSHEET'!A59 -> 53 | B63: ='SCHEDULE OF VALUE WORKSHEET'!B59 -> DOORS | D63: =SUM('SCHEDULE OF VALUE WORKSHEET'!E59) -> 204087.33 | E63: =SUM('Draw #3'!E63:F63) -> 0 | F63: 0 | G63: =SUM('Draw #3'!G63)+'Draw #4'!F63 -> 204087.33 | H63: =SUM(G63-J63) -> 204087.33 | I63: 0 | J63: =SUM(I63+'Draw #3'!J63) -> 0 | K63: =IF(J63=0,"",J63/G63)
A64: ='SCHEDULE OF VALUE WORKSHEET'!A60 -> 54 | B64: ='SCHEDULE OF VALUE WORKSHEET'!B60 -> WINDOWS | D64: =SUM('SCHEDULE OF VALUE WORKSHEET'!E60) -> 106274.25 | E64: =SUM('Draw #3'!E64:F64) -> 0 | F64: 0 | G64: =SUM('Draw #3'!G64)+'Draw #4'!F64 -> 106274.25 | H64: =SUM(G64-J64) -> 106274.25 | I64: 0 | J64: =SUM(I64+'Draw #3'!J64) -> 0 | K64: =IF(J64=0,"",J64/G64)
...

Sheet Draw #5
A1: GENESIS CAPITAL DRAW FORM
B3: CLIENT: | C3: ='SCHEDULE OF VALUE WORKSHEET'!$B$3 -> Angeleno Investments | I3: TOTAL COMPLETED TO DATE: | J3: =SUM(J137) -> 0 | K3: =SUM(J3)/J7 -> #REF!
B4: DATE: | C4: =TODAY() -> 45978 | I4: REMAINING $ IN BUDGET: | J4: =SUM(H137) -> #REF!
B5: PROJECT: | C5: ='SCHEDULE OF VALUE WORKSHEET'!B5 -> 10910 Huston Street | I5: ORIGINAL SCHEDULE OF VALUES: | J5: =SUM(D137) -> #REF!
B6: DRAW REQUEST: | C6: =SUM(I137) -> 0 | I6: CHANGE ORDERS: | J6: =SUM(F137) -> 0
I7: REVISED SCHEDULE OF VALUES: | J7: =SUM(G137) -> #REF!
B8: DESCRIPTION OF WORK | D8: SCHEDULED VALUES | E8: PREVIOUS | F8: + / - CHANGES | G8: REVISED VALUES | H8: REMAINING | I8: DRAW | J8: COMPLETED AND
E9: CHANGES | H9: BUDGET | I9: 5 | J9: STORED TO DATE
A10: ='SCHEDULE OF VALUE WORKSHEET'!A7 -> 1 | B10: ='SCHEDULE OF VALUE WORKSHEET'!B7 -> SOFT COSTS | D10: =SUM('SCHEDULE OF VALUE WORKSHEET'!E7) -> 0 | E10: =SUM('Draw #4'!E10:F10) -> 0 | F10: 0 | G10: =SUM('Draw #4'!G10)+'Draw #5'!F10 -> 0 | H10: =SUM(G10-J10) -> 0 | I10: 0 | J10: =SUM(I10+'Draw #4'!J10) -> 0 | K10: =IF(J10=0,"",J10/G10)
A11: ='SCHEDULE OF VALUE WORKSHEET'!A8 -> 2 | B11: ='SCHEDULE OF VALUE WORKSHEET'!B8 -> Site Security | D11: =SUM('SCHEDULE OF VALUE WORKSHEET'!E8) -> 10580.63 | E11: =SUM('Draw #4'!E11:F11) -> 0 | F11: 0 | G11: =SUM('Draw #4'!G11)+'Draw #5'!F11 -> 10580.63 | H11: =SUM(G11-J11) -> 10580.63 | I11: 0 | J11: =SUM(I11+'Draw #4'!J11) -> 0 | K11: =IF(J11=0,"",J11/G11)
A12: ='SCHEDULE OF VALUE WORKSHEET'!A9 -> 3 | B12: ='SCHEDULE OF VALUE WORKSHEET'!B9 -> Soils Inspection | D12: =SUM('SCHEDULE OF VALUE WORKSHEET'!E9) -> 0 | E12: =SUM('Draw #4'!E12:F12) -> 0 | F12: 0 | G12: =SUM('Draw #4'!G12)+'Draw #5'!F12 -> 0 | H12: =SUM(G12-J12) -> 0 | I12: 0 | J12: =SUM(I12+'Draw #4'!J12) -> 0 | K12: =IF(J12=0,"",J12/G12)
A13: ='SCHEDULE OF VALUE WORKSHEET'!A10 -> 4 | B13: ='SCHEDULE OF VALUE WORKSHEET'!B10 -> Offsites (Transformer) | D13: =SUM('SCHEDULE OF VALUE WORKSHEET'!E10) -> 20000 | E13: =SUM('Draw #4'!E13:F13) -> 0 | F13: 0 | G13: =SUM('Draw #4'!G13)+'Draw #5'!F13 -> 20000 | H13: =SUM(G13-J13) -> 20000 | I13: 0 | J13: =SUM(I13+'Draw #4'!J13) -> 0 | K13: =IF(J13=0,"",J13/G13)
A14: ='SCHEDULE OF VALUE WORKSHEET'!A11 -> 5 | B14: ='SCHEDULE OF VALUE WORKSHEET'!B11 -> Plan Check Fees | D14: =SUM('SCHEDULE OF VALUE WORKSHEET'!E11) -> 0 | E14: =SUM('Draw #4'!E14:F14) -> 0 | F14: 0 | G14: =SUM('Draw #4'!G14)+'Draw #5'!F14 -> 0 | H14: =SUM(G14-J14) -> 0 | I14: 0 | J14: =SUM(I14+'Draw #4'!J14) -> 0 | K14: =IF(J14=0,"",J14/G14)
A15: ='SCHEDULE OF VALUE WORKSHEET'!A12 -> 6 | B15: ='SCHEDULE OF VALUE WORKSHEET'!B12 -> Permits | D15: =SUM('SCHEDULE OF VALUE WORKSHEET'!E12) -> 0 | E15: =SUM('Draw #4'!E15:F15) -> 0 | F15: 0 | G15: =SUM('Draw #4'!G15)+'Draw #5'!F15 -> 0 | H15: =SUM(G15-J15) -> 0 | I15: 0 | J15: =SUM(I15+'Draw #4'!J15) -> 0 | K15: =IF(J15=0,"",J15/G15)
A16: ='SCHEDULE OF VALUE WORKSHEET'!A13 -> 7 | B16: ='SCHEDULE OF VALUE WORKSHEET'!B13 -> Survey | D16: =SUM('SCHEDULE OF VALUE WORKSHEET'!E13) -> 0 | E16: =SUM('Draw #4'!E16:F16) -> 0 | F16: 0 | G16: =SUM('Draw #4'!G16)+'Draw #5'!F16 -> 0 | H16: =SUM(G16-J16) -> 0 | I16: 0 | J16: =SUM(I16+'Draw #4'!J16) -> 0 | K16: =IF(J16=0,"",J16/G16)
A17: ='SCHEDULE OF VALUE WORKSHEET'!A14 -> 8 | B17: ='SCHEDULE OF VALUE WORKSHEET'!B14 -> Soils Engineer | D17: =SUM('SCHEDULE OF VALUE WORKSHEET'!E14) -> 0 | E17: =SUM('Draw #4'!E17:F17) -> 0 | F17: 0 | G17: =SUM('Draw #4'!G17)+'Draw #5'!F17 -> 0 | H17: =SUM(G17-J17) -> 0 | I17: 0 | J17: =SUM(I17+'Draw #4'!J17) -> 0 | K17: =IF(J17=0,"",J17/G17)
A18: ='SCHEDULE OF VALUE WORKSHEET'!A15 -> 9 | B18: ='SCHEDULE OF VALUE WORKSHEET'!B15 -> Soils Permit + T24 | D18: =SUM('SCHEDULE OF VALUE WORKSHEET'!E15) -> 2500 | E18: =SUM('Draw #4'!E18:F18) -> 0 | F18: 0 | G18: =SUM('Draw #4'!G18)+'Draw #5'!F18 -> 2500 | H18: =SUM(G18-J18) -> 2500 | I18: 0 | J18: =SUM(I18+'Draw #4'!J18) -> 0 | K18: =IF(J18=0,"",J18/G18)
A19: ='SCHEDULE OF VALUE WORKSHEET'!A16 -> 10 | B19: ='SCHEDULE OF VALUE WORKSHEET'!B16 -> Special Inspections - Deputy | D19: =SUM('SCHEDULE OF VALUE WORKSHEET'!E16) -> 15000 | E19: =SUM('Draw #4'!E19:F19) -> 0 | F19: 0 | G19: =SUM('Draw #4'!G19)+'Draw #5'!F19 -> 15000 | H19: =SUM(G19-J19) -> 15000 | I19: 0 | J19: =SUM(I19+'Draw #4'!J19) -> 0 | K19: =IF(J19=0,"",J19/G19)
A20: ='SCHEDULE OF VALUE WORKSHEET'!A17 -> 11 | B20: ='SCHEDULE OF VALUE WORKSHEET'!B17 -> Architect | D20: =SUM('SCHEDULE OF VALUE WORKSHEET'!E17) -> 0 | E20: =SUM('Draw #4'!E20:F20) -> 0 | F20: 0 | G20: =SUM('Draw #4'!G20)+'Draw #5'!F20 -> 0 | H20: =SUM(G20-J20) -> 0 | I20: 0 | J20: =SUM(I20+'Draw #4'!J20) -> 0 | K20: =IF(J20=0,"",J20/G20)
A21: ='SCHEDULE OF VALUE WORKSHEET'!A18 -> 12 | B21: ='SCHEDULE OF VALUE WORKSHEET'!B18 -> Structural Engineer | D21: =SUM('SCHEDULE OF VALUE WORKSHEET'!E18) -> 0 | E21: =SUM('Draw #4'!E21:F21) -> 0 | F21: 0 | G21: =SUM('Draw #4'!G21)+'Draw #5'!F21 -> 0 | H21: =SUM(G21-J21) -> 0 | I21: 0 | J21: =SUM(I21+'Draw #4'!J21) -> 0 | K21: =IF(J21=0,"",J21/G21)
... A45: ='SCHEDULE OF VALUE WORKSHEET'!A42 -> 36 | B45: ='SCHEDULE OF VALUE WORKSHEET'!B42 -> Construction Management / Observation (OO) | D45: =SUM('SCHEDULE OF VALUE WORKSHEET'!E42) -> 49427.9 | E45: =SUM('Draw #4'!E45:F45) -> 0 | F45: 0 | G45: =SUM('Draw #4'!G45)+'Draw #5'!F45 -> 49427.9 | H45: =SUM(G45-J45) -> 49427.9 | I45: 0 | J45: =SUM(I45+'Draw #4'!J45) -> 0 | K45: =IF(J45=0,"",J45/G45)
A46: ='SCHEDULE OF VALUE WORKSHEET'!#REF! -> #REF! | B46: ='SCHEDULE OF VALUE WORKSHEET'!#REF! -> #REF! | D46: =SUM('SCHEDULE OF VALUE WORKSHEET'!#REF!) -> #REF! | E46: =SUM('Draw #4'!E46:F46) -> 0 | F46: 0 | G46: =SUM('Draw #4'!G46)+'Draw #5'!F46 -> #REF! | H46: =SUM(G46-J46) -> #REF! | I46: 0 | J46: =SUM(I46+'Draw #4'!J46) -> 0 | K46: =IF(J46=0,"",J46/G46)
A47: ='SCHEDULE OF VALUE WORKSHEET'!A43 -> 37 | B47: ='SCHEDULE OF VALUE WORKSHEET'!B43 -> CMFA Startup Fee | D47: =SUM('SCHEDULE OF VALUE WORKSHEET'!E43) -> 22800 | E47: =SUM('Draw #4'!E47:F47) -> 0 | F47: 0 | G47: =SUM('Draw #4'!G47)+'Draw #5'!F47 -> 22800 | H47: =SUM(G47-J47) -> 22800 | I47: 0 | J47: =SUM(I47+'Draw #4'!J47) -> 0 | K47: =IF(J47=0,"",J47/G47)
A48: ='SCHEDULE OF VALUE WORKSHEET'!A44 -> 38 | B48: ='SCHEDULE OF VALUE WORKSHEET'!B44 -> Non-Profit Start Up Fee | D48: =SUM('SCHEDULE OF VALUE WORKSHEET'!E44) -> 25000 | E48: =SUM('Draw #4'!E48:F48) -> 0 | F48: 0 | G48: =SUM('Draw #4'!G48)+'Draw #5'!F48 -> 25000 | H48: =SUM(G48-J48) -> 25000 | I48: 0 | J48: =SUM(I48+'Draw #4'!J48) -> 0 | K48: =IF(J48=0,"",J48/G48)
A49: ='SCHEDULE OF VALUE WORKSHEET'!A45 -> 39 | B49: ='SCHEDULE OF VALUE WORKSHEET'!B45 -> CMFA Construction Fee | D49: =SUM('SCHEDULE OF VALUE WORKSHEET'!E45) -> 12000 | E49: =SUM('Draw #4'!E49:F49) -> 0 | F49: 0 | G49: =SUM('Draw #4'!G49)+'Draw #5'!F49 -> 12000 | H49: =SUM(G49-J49) -> 12000 | I49: 0 | J49: =SUM(I49+'Draw #4'!J49) -> 0 | K49: =IF(J49=0,"",J49/G49)
A50: ='SCHEDULE OF VALUE WORKSHEET'!A46 -> 40 | B50: ='SCHEDULE OF VALUE WORKSHEET'!B46 -> Non-Profit Construction Fee | D50: =SUM('SCHEDULE OF VALUE WORKSHEET'!E46) -> 10000 | E50: =SUM('Draw #4'!E50:F50) -> 0 | F50: 0 | G50: =SUM('Draw #4'!G50)+'Draw #5'!F50 -> 10000 | H50: =SUM(G50-J50) -> 10000 | I50: 0 | J50: =SUM(I50+'Draw #4'!J50) -> 0 | K50: =IF(J50=0,"",J50/G50)
A51: ='SCHEDULE OF VALUE WORKSHEET'!A47 -> 41 | B51: ='SCHEDULE OF VALUE WORKSHEET'!B47 -> WTE Legal Costs for CMFA & Non-Profit Partner | D51: =SUM('SCHEDULE OF VALUE WORKSHEET'!E47) -> 20000 | E51: =SUM('Draw #4'!E51:F51) -> 0 | F51: 0 | G51: =SUM('Draw #4'!G51)+'Draw #5'!F51 -> 20000 | H51: =SUM(G51-J51) -> 20000 | I51: 0 | J51: =SUM(I51+'Draw #4'!J51) -> 0 | K51: =IF(J51=0,"",J51/G51)
